Workbook

Sheet PREÇO NACIONAL
B1: PREÇO PARA PUBLICAÇÃO - MAR.26
B2: a cada 10.000 Km ou 1 ano
B3: Ano / Modelo | C3: 1ª revisão | D3: 2ª revisão | E3: 3ª revisão | F3: 4ª revisão | G3: 5ª revisão | H3: 6ª revisão | I3: 7ª revisão | J3: 8ª revisão | K3: 9ª revisão | L3: 10ª revisão
B4: ='NOVO UNO 1.0 FIRE'!A1 -> UNO 1.0 FIRE | C4: ='NOVO UNO 1.0 FIRE'!O2 -> 608 | D4: ='NOVO UNO 1.0 FIRE'!P2 -> 813 | E4: ='NOVO UNO 1.0 FIRE'!Q2 -> 1098 | F4: ='NOVO UNO 1.0 FIRE'!R2 -> 915 | G4: ='NOVO UNO 1.0 FIRE'!S2 -> 676 | H4: ='NOVO UNO 1.0 FIRE'!T2 -> 2305 | I4: ='NOVO UNO 1.0 FIRE'!U2 -> 608 | J4: ='NOVO UNO 1.0 FIRE'!V2 -> 915 | ... L4: ='NOVO UNO 1.0 FIRE'!X2 -> 847 | M4: =SUM(C4:L4) -> 9883 | N4: =SUM(C4:H4) -> 6415
B5: ='NOVO UNO 1.0 FIREFLY'!A1 -> UNO 1.0 FIREFLY | C5: ='NOVO UNO 1.0 FIREFLY'!O2 -> 577 | D5: ='NOVO UNO 1.0 FIREFLY'!P2 -> 788 | E5: ='NOVO UNO 1.0 FIREFLY'!Q2 -> 611 | F5: ='NOVO UNO 1.0 FIREFLY'!R2 -> 1419 | G5: ='NOVO UNO 1.0 FIREFLY'!S2 -> 628 | H5: ='NOVO UNO 1.0 FIREFLY'!T2 -> 1171 | I5: ='NOVO UNO 1.0 FIREFLY'!U2 -> 577 | J5: ='NOVO UNO 1.0 FIREFLY'!V2 -> 1419 | ... L5: ='NOVO UNO 1.0 FIREFLY'!X2 -> 840 | M5: =SUM(C5:L5) -> 8641 | N5: =SUM(C5:H5) -> 5194
B6: ='NOVO UNO 1.3 FIREFLY'!A1 -> UNO 1.3 FIREFLY | C6: ='NOVO UNO 1.3 FIREFLY'!O2 -> 644 | D6: ='NOVO UNO 1.3 FIREFLY'!P2 -> 855 | E6: ='NOVO UNO 1.3 FIREFLY'!Q2 -> 678 | F6: ='NOVO UNO 1.3 FIREFLY'!R2 -> 1661 | G6: ='NOVO UNO 1.3 FIREFLY'!S2 -> 695 | H6: ='NOVO UNO 1.3 FIREFLY'!T2 -> 1238 | I6: ='NOVO UNO 1.3 FIREFLY'!U2 -> 644 | J6: ='NOVO UNO 1.3 FIREFLY'!V2 -> 1661 | ... L6: ='NOVO UNO 1.3 FIREFLY'!X2 -> 906 | M6: =SUM(C6:L6) -> 9660 | N6: =SUM(C6:H6) -> 5771
B7: ='PALIO WEEKEND 1.4'!A1 -> PALIO WEEKEND 1.4 | C7: ='PALIO WEEKEND 1.4'!O2 -> 600 | D7: ='PALIO WEEKEND 1.4'!P2 -> 751 | E7: ='PALIO WEEKEND 1.4'!Q2 -> 1090 | F7: ='PALIO WEEKEND 1.4'!R2 -> 870 | G7: ='PALIO WEEKEND 1.4'!S2 -> 635 | H7: ='PALIO WEEKEND 1.4'!T2 -> 2244 | I7: ='PALIO WEEKEND 1.4'!U2 -> 600 | J7: ='PALIO WEEKEND 1.4'!V2 -> 870 | ... L7: ='PALIO WEEKEND 1.4'!X2 -> 819 | M7: =SUM(C7:L7) -> 9569 | N7: =SUM(C7:H7) -> 6190
B8: ='PALIO WEEKEND 1.8'!A1 -> PALIO WEEKEND 1.8 | C8: ='PALIO WEEKEND 1.8'!O2 -> 794 | D8: ='PALIO WEEKEND 1.8'!P2 -> 989 | E8: ='PALIO WEEKEND 1.8'!Q2 -> 1080 | F8: ='PALIO WEEKEND 1.8'!R2 -> 1075 | G8: ='PALIO WEEKEND 1.8'!S2 -> 812 | H8: ='PALIO WEEKEND 1.8'!T2 -> 1847 | I8: ='PALIO WEEKEND 1.8'!U2 -> 794 | J8: ='PALIO WEEKEND 1.8'!V2 -> 1075 | ... L8: ='PALIO WEEKEND 1.8'!X2 -> 1041 | M8: =SUM(C8:L8) -> 10587 | N8: =SUM(C8:H8) -> 6597
B9: =FIORINO!A15 -> FIORINO 1.4 (21/22) | C9: =FIORINO!T16 -> 532 | D9: =FIORINO!U16 -> 719 | E9: =FIORINO!V16 -> 1127 | F9: =FIORINO!W16 -> 925 | G9: =FIORINO!X16 -> 583 | H9: =FIORINO!Y16 -> 2266 | I9: =FIORINO!Z16 -> 532 | J9: =FIORINO!AA16 -> 771 | ... L9: =FIORINO!AC16 -> 925 | M9: =SUM(C9:L9) -> 9507 | N9: =SUM(C9:H9) -> 6152
B10: =FIORINO!A1 -> FIORINO 1.4 (21/21) | C10: =FIORINO!T2 -> 600 | D10: =FIORINO!U2 -> 805 | E10: =FIORINO!V2 -> 1161 | F10: =FIORINO!W2 -> 908 | G10: =FIORINO!X2 -> 669 | H10: =FIORINO!Y2 -> 2369 | I10: =FIORINO!Z2 -> 600 | J10: =FIORINO!AA2 -> 908 | ... L10: =FIORINO!AC2 -> 925 | M10: =SUM(C10:L10) -> 10106 | N10: =SUM(C10:H10) -> 6512
B11: =FIORINO!A30 -> FIORINO 1.3 | C11: =FIORINO!T31 -> 630 | D11: =FIORINO!U31 -> 824 | E11: =FIORINO!V31 -> 647 | F11: =FIORINO!W31 -> 1647 | G11: =FIORINO!X31 -> 681 | H11: =FIORINO!Y31 -> 998 | I11: =FIORINO!Z31 -> 630 | J11: =FIORINO!AA31 -> 1647 | ... L11: =FIORINO!AC31 -> 875 | M11: =SUM(C11:L11) -> 9226 | N11: =SUM(C11:H11) -> 5427
B12: ='NOVA STRADA 1.3'!A1 -> NOVA STRADA 1.3 AT | C12: ='NOVA STRADA 1.3'!T2 -> 627 | D12: ='NOVA STRADA 1.3'!U2 -> 821 | E12: ='NOVA STRADA 1.3'!V2 -> 644 | F12: ='NOVA STRADA 1.3'!W2 -> 1644 | G12: ='NOVA STRADA 1.3'!X2 -> 678 | H12: ='NOVA STRADA 1.3'!Y2 -> 998 | I12: ='NOVA STRADA 1.3'!Z2 -> 627 | J12: ='NOVA STRADA 1.3'!AA2 -> 1644 | ... L12: ='NOVA STRADA 1.3'!AC2 -> 872 | M12: =SUM(C12:L12) -> 9199 | N12: =SUM(C12:H12) -> 5412
B13: ='NOVA STRADA 1.4'!A1 -> NOVA STRADA 1.4 | C13: ='NOVA STRADA 1.4'!T2 -> 532 | D13: ='NOVA STRADA 1.4'!U2 -> 719 | E13: ='NOVA STRADA 1.4'!V2 -> 1127 | F13: ='NOVA STRADA 1.4'!W2 -> 925 | G13: ='NOVA STRADA 1.4'!X2 -> 583 | H13: ='NOVA STRADA 1.4'!Y2 -> 2361 | I13: ='NOVA STRADA 1.4'!Z2 -> 532 | J13: ='NOVA STRADA 1.4'!AA2 -> 771 | ... L13: ='NOVA STRADA 1.4'!AC2 -> 925 | M13: =SUM(C13:L13) -> 9602 | N13: =SUM(C13:H13) -> 6247
B14: ='NOVA STRADA 1.0T'!A1 -> NOVA STRADA 1.0T | C14: ='NOVA STRADA 1.0T'!T2 -> 746 | D14: ='NOVA STRADA 1.0T'!U2 -> 764 | E14: ='NOVA STRADA 1.0T'!V2 -> 927 | F14: ='NOVA STRADA 1.0T'!W2 -> 764 | G14: ='NOVA STRADA 1.0T'!X2 -> 781 | H14: ='NOVA STRADA 1.0T'!Y2 -> 1460 | I14: ='NOVA STRADA 1.0T'!Z2 -> 746 | J14: ='NOVA STRADA 1.0T'!AA2 -> 764 | ... L14: ='NOVA STRADA 1.0T'!AC2 -> 798 | M14: =SUM(C14:L14) -> 8677 | N14: =SUM(C14:H14) -> 5442
B15: ='ARGO 1.0'!A1 -> ARGO 1.0 | C15: ='ARGO 1.0'!T2 -> 577 | D15: ='ARGO 1.0'!U2 -> 823 | E15: ='ARGO 1.0'!V2 -> 594 | F15: ='ARGO 1.0'!W2 -> 1675 | G15: ='ARGO 1.0'!X2 -> 628 | H15: ='ARGO 1.0'!Y2 -> 1051 | I15: ='ARGO 1.0'!Z2 -> 577 | J15: ='ARGO 1.0'!AA2 -> 1675 | ... L15: ='ARGO 1.0'!AC2 -> 874 | M15: =SUM(C15:L15) -> 9068 | N15: =SUM(C15:H15) -> 5348
B16: ='ARGO 1.3'!A1 -> ARGO 1.3 | C16: ='ARGO 1.3'!T2 -> 644 | D16: ='ARGO 1.3'!U2 -> 889 | E16: ='ARGO 1.3'!V2 -> 661 | F16: ='ARGO 1.3'!W2 -> 1918 | G16: ='ARGO 1.3'!X2 -> 695 | H16: ='ARGO 1.3'!Y2 -> 1118 | I16: ='ARGO 1.3'!Z2 -> 644 | J16: ='ARGO 1.3'!AA2 -> 1918 | ... L16: ='ARGO 1.3'!AC2 -> 940 | M16: =SUM(C16:L16) -> 10088 | N16: =SUM(C16:H16) -> 5925
B17: ='ARGO 1.8'!A1 -> ARGO 1.8 | C17: ='ARGO 1.8'!O2 -> 688 | D17: ='ARGO 1.8'!P2 -> 928 | E17: ='ARGO 1.8'!Q2 -> 705 | F17: ='ARGO 1.8'!R2 -> 1082 | G17: ='ARGO 1.8'!S2 -> 739 | H17: ='ARGO 1.8'!T2 -> 2016 | I17: ='ARGO 1.8'!U2 -> 705 | J17: ='ARGO 1.8'!V2 -> 1082 | ... L17: ='ARGO 1.8'!X2 -> 980 | M17: =SUM(C17:L17) -> 9630 | N17: =SUM(C17:H17) -> 6158
B18: ='GRAND SIENA 1.0'!A1 -> GRAND SIENA 1.0 | C18: ='GRAND SIENA 1.0'!O2 -> 600 | D18: ='GRAND SIENA 1.0'!P2 -> 788 | E18: ='GRAND SIENA 1.0'!Q2 -> 1193 | F18: ='GRAND SIENA 1.0'!R2 -> 908 | G18: ='GRAND SIENA 1.0'!S2 -> 652 | H18: ='GRAND SIENA 1.0'!T2 -> 2380 | I18: ='GRAND SIENA 1.0'!U2 -> 600 | J18: ='GRAND SIENA 1.0'!V2 -> 908 | ... L18: ='GRAND SIENA 1.0'!X2 -> 856 | M18: =SUM(C18:L18) -> 10078 | N18: =SUM(C18:H18) -> 6521
B19: ='GRAND SIENA 1.4'!A1 -> GRAND SIENA 1.4 | C19: ='GRAND SIENA 1.4'!O2 -> 600 | D19: ='GRAND SIENA 1.4'!P2 -> 788 | E19: ='GRAND SIENA 1.4'!Q2 -> 1161 | F19: ='GRAND SIENA 1.4'!R2 -> 908 | G19: ='GRAND SIENA 1.4'!S2 -> 652 | H19: ='GRAND SIENA 1.4'!T2 -> 2377 | I19: ='GRAND SIENA 1.4'!U2 -> 600 | J19: ='GRAND SIENA 1.4'!V2 -> 908 | ... L19: ='GRAND SIENA 1.4'!X2 -> 856 | M19: =SUM(C19:L19) -> 10011 | N19: =SUM(C19:H19) -> 6486
B20: ='MOBI FIRE'!A1 -> MOBI 1.0 FIRE | C20: ='MOBI FIRE'!T2 -> 583 | D20: ='MOBI FIRE'!U2 -> 788 | E20: ='MOBI FIRE'!V2 -> 1176 | F20: ='MOBI FIRE'!W2 -> 856 | G20: ='MOBI FIRE'!X2 -> 789 | H20: ='MOBI FIRE'!Y2 -> 2479 | I20: ='MOBI FIRE'!Z2 -> 583 | J20: ='MOBI FIRE'!AA2 -> 856 | ... L20: ='MOBI FIRE'!AC2 -> 839 | M20: =SUM(C20:L20) -> 10125 | N20: =SUM(C20:H20) -> 6671
B21: ='MOBI FIREFLY'!A1 -> MOBI FIREFLY | C21: ='MOBI FIREFLY'!T2 -> 667 | D21: ='MOBI FIREFLY'!U2 -> 788 | E21: ='MOBI FIREFLY'!V2 -> 701 | F21: ='MOBI FIREFLY'!W2 -> 1419 | G21: ='MOBI FIREFLY'!X2 -> 718 | H21: ='MOBI FIREFLY'!Y2 -> 1171 | I21: ='MOBI FIREFLY'!Z2 -> 667 | J21: ='MOBI FIREFLY'!AA2 -> 1419 | ... L21: ='MOBI FIREFLY'!AC2 -> 840 | M21: =SUM(C21:L21) -> 9091 | N21: =SUM(C21:H21) -> 5464
B22: =DOBLO!A1 -> DOBLO 1.8 | C22: =DOBLO!O2 -> 367 | D22: =DOBLO!P2 -> 989 | E22: =DOBLO!Q2 -> 1080 | F22: =DOBLO!R2 -> 1075 | G22: =DOBLO!S2 -> 829 | H22: =DOBLO!T2 -> 1847 | I22: =DOBLO!U2 -> 794 | J22: =DOBLO!V2 -> 1075 | ... L22: =DOBLO!X2 -> 1041 | M22: =SUM(C22:L22) -> 10177 | N22: =SUM(C22:H22) -> 6187
B23: ='CRONOS 1.0'!A1 -> CRONOS 1.0 até MY26 | C23: ='CRONOS 1.0'!T2 -> 577 | D23: ='CRONOS 1.0'!U2 -> 823 | E23: ='CRONOS 1.0'!V2 -> 594 | F23: ='CRONOS 1.0'!W2 -> 1675 | G23: ='CRONOS 1.0'!X2 -> 628 | H23: ='CRONOS 1.0'!Y2 -> 1051 | I23: ='CRONOS 1.0'!Z2 -> 577 | J23: ='CRONOS 1.0'!AA2 -> 1675 | ... L23: ='CRONOS 1.0'!AC2 -> 874 | M23: =SUM(C23:L23) -> 9068 | N23: =SUM(C23:H23) -> 5348
B24: ='CRONOS 1.3'!A1 -> CRONOS 1.3 até MY26 | C24: ='CRONOS 1.3'!T2 -> 644 | D24: ='CRONOS 1.3'!U2 -> 889 | E24: ='CRONOS 1.3'!V2 -> 661 | F24: ='CRONOS 1.3'!W2 -> 1918 | G24: ='CRONOS 1.3'!X2 -> 695 | H24: ='CRONOS 1.3'!Y2 -> 1118 | I24: ='CRONOS 1.3'!Z2 -> 644 | J24: ='CRONOS 1.3'!AA2 -> 1918 | ... L24: ='CRONOS 1.3'!AC2 -> 940 | M24: =SUM(C24:L24) -> 10088 | N24: =SUM(C24:H24) -> 5925
B25: ='CRONOS 1.8'!A1 -> CRONOS 1.8 | C25: ='CRONOS 1.8'!T2 -> 688 | D25: ='CRONOS 1.8'!U2 -> 928 | E25: ='CRONOS 1.8'!V2 -> 705 | F25: ='CRONOS 1.8'!W2 -> 1082 | G25: ='CRONOS 1.8'!X2 -> 739 | H25: ='CRONOS 1.8'!Y2 -> 2016 | I25: ='CRONOS 1.8'!Z2 -> 705 | J25: ='CRONOS 1.8'!AA2 -> 1082 | ... L25: ='CRONOS 1.8'!AC2 -> 980 | M25: =SUM(C25:L25) -> 9630 | N25: =SUM(C25:H25) -> 6158
B26: ='PULSE 1.0T'!A1 -> PULSE 1.0T AT | C26: ='PULSE 1.0T'!T2 -> 746 | D26: ='PULSE 1.0T'!U2 -> 764 | E26: ='PULSE 1.0T'!V2 -> 927 | F26: ='PULSE 1.0T'!W2 -> 764 | G26: ='PULSE 1.0T'!X2 -> 781 | H26: ='PULSE 1.0T'!Y2 -> 1460 | I26: ='PULSE 1.0T'!Z2 -> 746 | J26: ='PULSE 1.0T'!AA2 -> 764 | ... L26: ='PULSE 1.0T'!AC2 -> 798 | M26: =SUM(C26:L26) -> 8677 | N26: =SUM(C26:H26) -> 5442
B27: ='PULSE 1.3'!A1 -> PULSE 1.3 AT | C27: ='PULSE 1.3'!T2 -> 627 | D27: ='PULSE 1.3'!U2 -> 714 | E27: ='PULSE 1.3'!V2 -> 716 | F27: ='PULSE 1.3'!W2 -> 1520 | G27: ='PULSE 1.3'!X2 -> 678 | H27: ='PULSE 1.3'!Y2 -> 947 | I27: ='PULSE 1.3'!Z2 -> 627 | J27: ='PULSE 1.3'!AA2 -> 1520 | ... L27: ='PULSE 1.3'!AC2 -> 765 | M27: =SUM(C27:L27) -> 8830 | N27: =SUM(C27:H27) -> 5202
B28: ='PULSE ABARTH'!A1 -> PULSE ABARTH 1.3T | C28: ='PULSE ABARTH'!O2 -> 861 | D28: ='PULSE ABARTH'!P2 -> 992 | E28: ='PULSE ABARTH'!Q2 -> 861 | F28: ='PULSE ABARTH'!R2 -> 1009 | G28: ='PULSE ABARTH'!S2 -> 895 | H28: ='PULSE ABARTH'!T2 -> 1697 | I28: ='PULSE ABARTH'!U2 -> 861 | J28: ='PULSE ABARTH'!V2 -> 1009 | ... L28: ='PULSE ABARTH'!X2 -> 1026 | M28: =SUM(C28:L28) -> 10072 | N28: =SUM(C28:H28) -> 6315
B29: ='FASTBACK 1.0T'!A1 -> FASTBACK 1.0T | C29: ='FASTBACK 1.0T'!T2 -> 755 | D29: ='FASTBACK 1.0T'!U2 -> 772 | E29: ='FASTBACK 1.0T'!V2 -> 935 | F29: ='FASTBACK 1.0T'!W2 -> 772 | G29: ='FASTBACK 1.0T'!X2 -> 789 | H29: ='FASTBACK 1.0T'!Y2 -> 1469 | I29: ='FASTBACK 1.0T'!Z2 -> 755 | J29: ='FASTBACK 1.0T'!AA2 -> 772 | ... L29: ='FASTBACK 1.0T'!AC2 -> 807 | M29: =SUM(C29:L29) -> 8761 | N29: =SUM(C29:H29) -> 5492
B30: ='FASTBACK 1.3T'!A1 -> FASTBACK ABARTH 1.3T | C30: ='FASTBACK 1.3T'!T2 -> 861 | D30: ='FASTBACK 1.3T'!U2 -> 992 | E30: ='FASTBACK 1.3T'!V2 -> 861 | F30: ='FASTBACK 1.3T'!W2 -> 1009 | G30: ='FASTBACK 1.3T'!X2 -> 895 | H30: ='FASTBACK 1.3T'!Y2 -> 1697 | I30: ='FASTBACK 1.3T'!Z2 -> 861 | J30: ='FASTBACK 1.3T'!AA2 -> 1009 | ... L30: ='FASTBACK 1.3T'!AC2 -> 1026 | M30: =SUM(C30:L30) -> 10072 | N30: =SUM(C30:H30) -> 6315
B31: ='TORO 1.8'!A1 -> TORO 1.8 | C31: ='TORO 1.8'!O2 -> 433 | D31: ='TORO 1.8'!P2 -> 1031 | E31: ='TORO 1.8'!Q2 -> 878 | F31: ='TORO 1.8'!R2 -> 1048 | G31: ='TORO 1.8'!S2 -> 980 | H31: ='TORO 1.8'!T2 -> 2221 | I31: ='TORO 1.8'!U2 -> 878 | J31: ='TORO 1.8'!V2 -> 1048 | ... L31: ='TORO 1.8'!X2 -> 1167 | M31: =SUM(C31:L31) -> 10562 | N31: =SUM(C31:H31) -> 6591
B32: ='TORO 2.4'!A1 -> TORO 2.4 | C32: ='TORO 2.4'!O2 -> 634 | D32: ='TORO 2.4'!P2 -> 993 | E32: ='TORO 2.4'!Q2 -> 1044 | F32: ='TORO 2.4'!R2 -> 1078 | G32: ='TORO 2.4'!S2 -> 1027 | H32: ='TORO 2.4'!T2 -> 2409 | I32: ='TORO 2.4'!U2 -> 993 | J32: ='TORO 2.4'!V2 -> 1078 | ... L32: ='TORO 2.4'!X2 -> 1027 | M32: =SUM(C32:L32) -> 11327 | N32: =SUM(C32:H32) -> 7185
B33: ='TORO 1.3T'!A1 -> TORO 1.3T MY25 | C33: ='TORO 1.3T'!W2 -> 861 | D33: ='TORO 1.3T'!X2 -> 992 | E33: ='TORO 1.3T'!Y2 -> 861 | F33: ='TORO 1.3T'!Z2 -> 1009 | G33: ='TORO 1.3T'!AA2 -> 895 | H33: ='TORO 1.3T'!AB2 -> 1783 | I33: ='TORO 1.3T'!AC2 -> 861 | J33: ='TORO 1.3T'!AD2 -> 1009 | ... L33: ='TORO 1.3T'!AF2 -> 1026 | M33: =SUM(C33:L33) -> 10158 | N33: =SUM(C33:H33) -> 6401
B34: ='TORO 1.3T'!A13 -> TORO 1.3T MY26 | C34: ='TORO 1.3T'!W14 -> 1143 | D34: ='TORO 1.3T'!X14 -> 1274 | E34: ='TORO 1.3T'!Y14 -> 1143 | F34: ='TORO 1.3T'!Z14 -> 1154 | G34: ='TORO 1.3T'!AA14 -> 1177 | H34: ='TORO 1.3T'!AB14 -> 2065 | I34: ='TORO 1.3T'!AC14 -> 1143 | J34: ='TORO 1.3T'!AD14 -> 1154 | ... L34: ='TORO 1.3T'!AF14 -> 1308 | M34: =SUM(C34:L34) -> 12704 | N34: =SUM(C34:H34) -> 7956
B35: TITANO MANUAL | C35: =TITANO!T2 -> 2304 | D35: =TITANO!U2 -> 2294 | E35: =TITANO!V2 -> 1989 | F35: =TITANO!W2 -> 2328 | G35: =TITANO!X2 -> 2551 | H35: =TITANO!Y2 -> 2294 | I35: =TITANO!Z2 -> 1989 | J35: =TITANO!AA2 -> 4110 | ... L35: =TITANO!AC2 -> 2541 | M35: =SUM(C35:L35) -> 24704 | N35: =SUM(C35:H35) -> 13760
B36: TITANO AUTOMÁTICO | C36: =TITANO!T18 -> 2304 | D36: =TITANO!U18 -> 2294 | E36: =TITANO!V18 -> 1989 | F36: =TITANO!W18 -> 2328 | G36: =TITANO!X18 -> 2551 | H36: =TITANO!Y18 -> 2294 | I36: =TITANO!Z18 -> 1989 | J36: =TITANO!AA18 -> 4998 | ... L36: =TITANO!AC18 -> 2541 | M36: =SUM(C36:L36) -> 25592 | N36: =SUM(C36:H36) -> 13760
B37: =TITANO!A33 -> TITANO 2.2D MT | C37: =TITANO!T34 -> 1764 | D37: =TITANO!U34 -> 1664 | E37: =TITANO!V34 -> 1434 | F37: =TITANO!W34 -> 1783 | G37: =TITANO!X34 -> 1451 | H37: =TITANO!Y34 -> 2385 | I37: =TITANO!Z34 -> 1434 | J37: =TITANO!AA34 -> 1783 | ... L37: =TITANO!AC34 -> 1664 | M37: =SUM(C37:L37) -> 16796 | N37: =SUM(C37:H37) -> 10481
B38: =TITANO!A48 -> TITANO 2.2D AT | C38: =TITANO!T49 -> 1764 | D38: =TITANO!U49 -> 1664 | E38: =TITANO!V49 -> 1434 | F38: =TITANO!W49 -> 1783 | G38: =TITANO!X49 -> 1451 | H38: =TITANO!Y49 -> 1971 | I38: =TITANO!Z49 -> 1434 | J38: =TITANO!AA49 -> 1783 | ... L38: =TITANO!AC49 -> 1664 | M38: =SUM(C38:L38) -> 16382 | N38: =SUM(C38:H38) -> 10067
B39: =B1 -> PREÇO PARA PUBLICAÇÃO - MAR.26 | N39: =SUM(C39:H39) -> 0
B40: a cada 20.000 Km ou 1 ano | N40: =SUM(C40:H40) -> 0
...

Sheet CRONOS 1.0
A1: CRONOS 1.0 até MY26 | E1: PLANO DE MANUTENÇÃO | T1: CUSTOS DE MANUTENÇÃO [R$] | AI1: Total
T2: =MROUND(SUM(T4:T12),1) -> 577 | U2: =MROUND(SUM(U4:U12),1) -> 823 | V2: =MROUND(SUM(V4:V12),1) -> 594 | W2: =MROUND(SUM(W4:W12),1) -> 1675 | X2: =MROUND(SUM(X4:X12),1) -> 628 | Y2: =MROUND(SUM(Y4:Y12),1) -> 1051 | Z2: =MROUND(SUM(Z4:Z12),1) -> 577 | AA2: =MROUND(SUM(AA4:AA12),1) -> 1675 | ... AH2: =MROUND(SUM(AH4:AH12),1) -> 645 | AI2: =SUM(T2:AH2) -> 13794
A3: Nº | B3: ITENS DE SUBSTITUIÇÃO OBRIGATÓRIA | C3: PN | D3: P. PUB. | E3: 1a | F3: 2a | G3: 3a | H3: 4a | I3: 5a | J3: 6a | K3: 7a | L3: 8a | M3: 9a | N3: 10a | O3: 11 | P3: 12 | Q3: 13 | R3: 14 | S3: 15 | T3: 10000 | U3: 20000 | V3: 30000 | W3: 40000 | X3: 50000 | Y3: 60000 | Z3: 70000 | AA3: 80000 | AB3: 90000 | AC3: 100000 | AD3: =AC3+10000 -> 110000 | AE3: =AD3+10000 -> 120000 | AF3: =AE3+10000 -> 130000 | AG3: =AF3+10000 -> 140000 | AH3: =AG3+10000 -> 150000 | AI3: % 100 | AJ3: TTL 100
A4: 1 | B4: Filtro de Óleo do Motor | C4: 7094709 | D4: =VLOOKUP(C4,'[1]PREÇO ATUAL'!$A$1:$D$1048576,4,0) -> 79.9 | E4: 1 | F4: 1 | G4: 1 | H4: 1 | I4: 1 | J4: 1 | K4: 1 | L4: 1 | M4: 1 | N4: 1 | O4: 1 | P4: 1 | Q4: 1 | R4: 1 | S4: 1 | T4: =$D4*E4 -> 79.9 | U4: =$D4*F4 -> 79.9 | V4: =$D4*G4 -> 79.9 | W4: =$D4*H4 -> 79.9 | X4: =$D4*I4 -> 79.9 | Y4: =$D4*J4 -> 79.9 | Z4: =$D4*K4 -> 79.9 | AA4: =$D4*L4 -> 79.9 | ... AH4: =$D4*S4 -> 79.9 | AI4: =AJ4/$AI$2 -> 0.086885602 | AJ4: =SUM(T4:AH4) -> 1198.5
A5: 2 | B5: Filtro de Combustível | C5: 52162685 | D5: =VLOOKUP(C5,'[1]PREÇO ATUAL'!$A$1:$D$1048576,4,0) -> 35.9 | F5: 1 | H5: 1 | J5: 1 | L5: 1 | N5: 1 | P5: 1 | R5: 1 | T5: =$D5*E5 -> 0 | U5: =$D5*F5 -> 35.9 | V5: =$D5*G5 -> 0 | W5: =$D5*H5 -> 35.9 | X5: =$D5*I5 -> 0 | Y5: =$D5*J5 -> 35.9 | Z5: =$D5*K5 -> 0 | AA5: =$D5*L5 -> 35.9 | ... AH5: =$D5*S5 -> 0 | AI5: =AJ5/$AI$2 -> 0.018218066 | AJ5: =SUM(T5:AH5) -> 251.3
A6: 3 | B6: Filtro de Ar | C6: 52046268 | D6: =VLOOKUP(C6,'[1]PREÇO ATUAL'!$A$1:$D$1048576,4,0) -> 89.9 | F6: 1 | H6: 1 | J6: 1 | L6: 1 | N6: 1 | P6: 1 | R6: 1 | T6: =$D6*E6 -> 0 | U6: =$D6*F6 -> 89.9 | V6: =$D6*G6 -> 0 | W6: =$D6*H6 -> 89.9 | X6: =$D6*I6 -> 0 | Y6: =$D6*J6 -> 89.9 | Z6: =$D6*K6 -> 0 | AA6: =$D6*L6 -> 89.9 | ... AH6: =$D6*S6 -> 0 | AI6: =AJ6/$AI$2 -> 0.045621285 | AJ6: =SUM(T6:AH6) -> 629.3
A7: 4 | B7: Velas de Ignição | C7: 55267995 | D7: =VLOOKUP(C7,'[1]PREÇO ATUAL'!$A$1:$D$1048576,4,0) -> 175.9 | H7: 3 | L7: 3 | P7: 4 | T7: =$D7*E7 -> 0 | U7: =$D7*F7 -> 0 | V7: =$D7*G7 -> 0 | W7: =$D7*H7 -> 527.7 | X7: =$D7*I7 -> 0 | Y7: =$D7*J7 -> 0 | Z7: =$D7*K7 -> 0 | AA7: =$D7*L7 -> 527.7 | ... AH7: =$D7*S7 -> 0 | AI7: =AJ7/$AI$2 -> 0.12751921 | AJ7: =SUM(T7:AH7) -> 1759
A8: 5 | B8: Correia dos Órgãos Auxiliares | C8: 55267966 | D8: =VLOOKUP(C8,'[1]PREÇO ATUAL'!$A$1:$D$1048576,4,0) -> 143.23 | J8: 1 | P8: 1 | T8: =$D8*E8 -> 0 | U8: =$D8*F8 -> 0 | V8: =$D8*G8 -> 0 | W8: =$D8*H8 -> 0 | X8: =$D8*I8 -> 0 | Y8: =$D8*J8 -> 143.23 | Z8: =$D8*K8 -> 0 | AA8: =$D8*L8 -> 0 | ... AH8: =$D8*S8 -> 0 | AI8: =AJ8/$AI$2 -> 0.020767 | AJ8: =SUM(T8:AH8) -> 286.46
A9: 6 | B9: Óleo da caixa de cambio mecanica - SAE 75W – API GL4 | C9: 7095576 | D9: =VLOOKUP(C9,'[1]PREÇO ATUAL'!$A$1:$D$1048576,4,0) -> 165.97812 | P9: 2 | T9: =$D9*E9 -> 0 | U9: =$D9*F9 -> 0 | V9: =$D9*G9 -> 0 | W9: =$D9*H9 -> 0 | X9: =$D9*I9 -> 0 | Y9: =$D9*J9 -> 0 | Z9: =$D9*K9 -> 0 | AA9: =$D9*L9 -> 0 | ... AH9: =$D9*S9 -> 0 | AI9: =AJ9/$AI$2 -> 0.024065263 | AJ9: =SUM(T9:AH9) -> 331.95624
A10: 7 | B10: MOPAR BRAKE FLUID DOT 4 - A cada 2 anos | C10: K04549625LA_F | D10: =VLOOKUP(C10,'[1]PREÇO ATUAL'!$A$1:$D$1048576,4,0) -> 33.622493 | T10: =$D10*E10 -> 0 | U10: =$D10*F10 -> 0 | V10: =$D10*G10 -> 0 | W10: =$D10*H10 -> 0 | X10: =$D10*I10 -> 0 | Y10: =$D10*J10 -> 0 | Z10: =$D10*K10 -> 0 | AA10: =$D10*L10 -> 0 | ... AH10: =$D10*S10 -> 0 | AI10: =AJ10/$AI$2 -> 0 | AJ10: =SUM(T10:AH10) -> 0
A11: 8 | B11: MOPAR MAXPRO SYNTHETIC 0W20 (SP/GF-6A) | C11: K68218951LA_F | D11: =VLOOKUP(C11,'[1]PREÇO ATUAL'!$A$1:$D$1048576,4,0) -> 81.26 | E11: 2.54 | F11: 2.54 | G11: 2.54 | H11: 2.54 | I11: 2.54 | J11: 2.54 | K11: 2.54 | L11: 2.54 | M11: 2.54 | N11: 2.54 | O11: 2.54 | P11: 2.54 | Q11: 2.54 | R11: 2.54 | S11: 2.54 | T11: =$D11*E11 -> 206.4004 | U11: =$D11*F11 -> 206.4004 | V11: =$D11*G11 -> 206.4004 | W11: =$D11*H11 -> 206.4004 | X11: =$D11*I11 -> 206.4004 | Y11: =$D11*J11 -> 206.4004 | Z11: =$D11*K11 -> 206.4004 | AA11: =$D11*L11 -> 206.4004 | ... AH11: =$D11*S11 -> 206.4004 | AI11: =AJ11/$AI$2 -> 0.22444585 | AJ11: =SUM(T11:AH11) -> 3096.006
A12: 9 | B12: Tempo Padrão de Mão-De-Obra [horas] | C12: MO FIAT | D12: =VLOOKUP(C12,'[1]PREÇO ATUAL'!$A$1:$D$1048576,4,0) -> 342 | E12: 0.85 | F12: 1.2 | G12: 0.9 | H12: 2.15 | I12: 1 | J12: 1.45 | K12: 0.85 | L12: 2.15 | M12: 0.9 | N12: 1.35 | O12: 0.85 | P12: 1.5 | Q12: 0.85 | R12: 1.2 | S12: 1.05 | T12: =D12*E12 -> 290.7 | U12: =$D12*F12 -> 410.4 | V12: =$D12*G12 -> 307.8 | W12: =$D12*H12 -> 735.3 | X12: =$D12*I12 -> 342 | Y12: =$D12*J12 -> 495.9 | Z12: =$D12*K12 -> 290.7 | AA12: =$D12*L12 -> 735.3 | AB12: =$D12*M12 -> 307.8 | ... AH12: =$D12*S12 -> 359.1 | AI12: =AJ12/$AI$2 -> 0.45247934 | AJ12: =SUM(T12:AH12) -> 6241.5
A14: CRONOS 1.0 MY27 | E14: PLANO DE MANUTENÇÃO | T14: CUSTOS DE MANUTENÇÃO [R$] | AI14: Total
T15: =MROUND(SUM(T17:T26),1) -> 844 | U15: =MROUND(SUM(U17:U26),1) -> 1090 | V15: =MROUND(SUM(V17:V26),1) -> 862 | W15: =MROUND(SUM(W17:W26),1) -> 1960 | X15: =MROUND(SUM(X17:X26),1) -> 896 | Y15: =MROUND(SUM(Y17:Y26),1) -> 1175 | Z15: =MROUND(SUM(Z17:Z26),1) -> 844 | AA15: =MROUND(SUM(AA17:AA26),1) -> 1960 | ... AH15: =MROUND(SUM(AH17:AH26),1) -> 913 | AI15: =SUM(T15:AH15) -> 17045
A16: Nº | B16: ITENS DE SUBSTITUIÇÃO OBRIGATÓRIA | C16: PN | D16: P. PUB. | E16: 1a | F16: 2a | G16: 3a | H16: 4a | I16: 5a | J16: 6a | K16: 7a | L16: 8a | M16: 9a | N16: 10a | O16: 11 | P16: 12 | Q16: 13 | R16: 14 | S16: 15 | T16: 10000 | U16: 20000 | V16: 30000 | W16: 40000 | X16: 50000 | Y16: 60000 | Z16: 70000 | AA16: 80000 | AB16: 90000 | AC16: 100000 | AD16: =AC16+10000 -> 110000 | AE16: =AD16+10000 -> 120000 | AF16: =AE16+10000 -> 130000 | AG16: =AF16+10000 -> 140000 | AH16: =AG16+10000 -> 150000 | AI16: % 100 | AJ16: TTL 100
A17: 1 | B17: Filtro de óleo do motor | C17: 7094709 | D17: =VLOOKUP(C17,'[1]PREÇO ATUAL'!$A$1:$D$1048576,4,0) -> 79.9 | E17: 1 | F17: 1 | G17: 1 | H17: 1 | I17: 1 | J17: 1 | K17: 1 | L17: 1 | M17: 1 | N17: 1 | O17: 1 | P17: 1 | Q17: 1 | R17: 1 | S17: 1 | T17: =$D17*E17 -> 79.9 | U17: =$D17*F17 -> 79.9 | V17: =$D17*G17 -> 79.9 | W17: =$D17*H17 -> 79.9 | X17: =$D17*I17 -> 79.9 | Y17: =$D17*J17 -> 79.9 | Z17: =$D17*K17 -> 79.9 | AA17: =$D17*L17 -> 79.9 | ... AH17: =$D17*S17 -> 79.9 | AI17: =AJ17/$AI$2 -> 0.086885602 | AJ17: =SUM(T17:AH17) -> 1198.5
A18: 2 | B18: Filtro de Combustível | C18: 52162685 | D18: =VLOOKUP(C18,'[1]PREÇO ATUAL'!$A$1:$D$1048576,4,0) -> 35.9 | F18: 1 | H18: 1 | J18: 1 | L18: 1 | N18: 1 | P18: 1 | R18: 1 | T18: =$D18*E18 -> 0 | U18: =$D18*F18 -> 35.9 | V18: =$D18*G18 -> 0 | W18: =$D18*H18 -> 35.9 | X18: =$D18*I18 -> 0 | Y18: =$D18*J18 -> 35.9 | Z18: =$D18*K18 -> 0 | AA18: =$D18*L18 -> 35.9 | ... AH18: =$D18*S18 -> 0 | AI18: =AJ18/$AI$2 -> 0.018218066 | AJ18: =SUM(T18:AH18) -> 251.3
A19: 3 | B19: Elemento do filtro de ar do motor | C19: 52046268 | D19: =VLOOKUP(C19,'[1]PREÇO ATUAL'!$A$1:$D$1048576,4,0) -> 89.9 | F19: 1 | H19: 1 | J19: 1 | L19: 1 | N19: 1 | P19: 1 | R19: 1 | T19: =$D19*E19 -> 0 | U19: =$D19*F19 -> 89.9 | V19: =$D19*G19 -> 0 | W19: =$D19*H19 -> 89.9 | X19: =$D19*I19 -> 0 | Y19: =$D19*J19 -> 89.9 | Z19: =$D19*K19 -> 0 | AA19: =$D19*L19 -> 89.9 | ... AH19: =$D19*S19 -> 0 | AI19: =AJ19/$AI$2 -> 0.045621285 | AJ19: =SUM(T19:AH19) -> 629.3
A20: 4 | B20: Filtro de ar limpo do canister | C20: 7096883 | D20: =VLOOKUP(C20,'[1]PREÇO ATUAL'!$A$1:$D$1048576,4,0) -> 199.05 | E20: 1 | F20: 1 | G20: 1 | H20: 1 | I20: 1 | J20: 1 | K20: 1 | L20: 1 | M20: 1 | N20: 1 | O20: 1 | P20: 1 | Q20: 1 | R20: 1 | S20: 1 | T20: =$D20*E20 -> 199.05 | U20: =$D20*F20 -> 199.05 | V20: =$D20*G20 -> 199.05 | W20: =$D20*H20 -> 199.05 | X20: =$D20*I20 -> 199.05 | Y20: =$D20*J20 -> 199.05 | Z20: =$D20*K20 -> 199.05 | AA20: =$D20*L20 -> 199.05 | ... AH20: =$D20*S20 -> 199.05 | AI20: =AJ20/$AI$2 -> 0.21645281 | AJ20: =SUM(T20:AH20) -> 2985.75
A21: 5 | B21: Velas de ignição do motor (a cada 40.000 km, independente do tempo) | C21: 55267995 | D21: =VLOOKUP(C21,'[1]PREÇO ATUAL'!$A$1:$D$1048576,4,0) -> 175.9 | H21: 3 | L21: 3 | P21: 3 | T21: =$D21*E21 -> 0 | U21: =$D21*F21 -> 0 | V21: =$D21*G21 -> 0 | W21: =$D21*H21 -> 527.7 | X21: =$D21*I21 -> 0 | Y21: =$D21*J21 -> 0 | Z21: =$D21*K21 -> 0 | AA21: =$D21*L21 -> 527.7 | ... AH21: =$D21*S21 -> 0 | AI21: =AJ21/$AI$2 -> 0.11476729 | AJ21: =SUM(T21:AH21) -> 1583.1
A22: 6 | B22: Correia dos órgão auxiliares (a cada 60.000 km ou 4 anos, o que ocorrer primeiro) | C22: 55267966 | D22: =VLOOKUP(C22,'[1]PREÇO ATUAL'!$A$1:$D$1048576,4,0) -> 143.23 | T22: =$D22*E22 -> 0 | U22: =$D22*F22 -> 0 | V22: =$D22*G22 -> 0 | W22: =$D22*H22 -> 0 | X22: =$D22*I22 -> 0 | Y22: =$D22*J22 -> 0 | Z22: =$D22*K22 -> 0 | AA22: =$D22*L22 -> 0 | ... AH22: =$D22*S22 -> 0 | AI22: =AJ22/$AI$2 -> 0 | AJ22: =SUM(T22:AH22) -> 0
A23: 7 | B23: Substituição do óleo da caixa de cambio mecanica | C23: 7095576 | D23: =VLOOKUP(C23,'[1]PREÇO ATUAL'!$A$1:$D$1048576,4,0) -> 165.97812 | T23: =$D23*E23 -> 0 | U23: =$D23*F23 -> 0 | V23: =$D23*G23 -> 0 | W23: =$D23*H23 -> 0 | X23: =$D23*I23 -> 0 | Y23: =$D23*J23 -> 0 | Z23: =$D23*K23 -> 0 | AA23: =$D23*L23 -> 0 | ... AH23: =$D23*S23 -> 0 | AI23: =AJ23/$AI$2 -> 0 | AJ23: =SUM(T23:AH23) -> 0
A24: 8 | B24: Fluído de freio (a cada 40.000 km ou 2 anos, ou que ocurrer primeiro) | C24: K04549625LA_F | D24: =VLOOKUP(C24,'[1]PREÇO ATUAL'!$A$1:$D$1048576,4,0) -> 33.622493 | T24: =$D24*E24 -> 0 | U24: =$D24*F24 -> 0 | V24: =$D24*G24 -> 0 | W24: =$D24*H24 -> 0 | X24: =$D24*I24 -> 0 | Y24: =$D24*J24 -> 0 | Z24: =$D24*K24 -> 0 | AA24: =$D24*L24 -> 0 | ... AH24: =$D24*S24 -> 0 | AI24: =AJ24/$AI$2 -> 0 | AJ24: =SUM(T24:AH24) -> 0
A25: 9 | B25: Óleo do motor - MOPAR MAXPRO SYNTHETIC 0W20 (SP/GF-6A) | C25: K68218951LA_F | D25: =VLOOKUP(C25,'[1]PREÇO ATUAL'!$A$1:$D$1048576,4,0) -> 81.26 | E25: 2.54 | F25: 2.54 | G25: 2.54 | H25: 2.54 | I25: 2.54 | J25: 2.54 | K25: 2.54 | L25: 2.54 | M25: 2.54 | N25: 2.54 | O25: 2.54 | P25: 2.54 | Q25: 2.54 | R25: 2.54 | S25: 2.54 | T25: =D25*E25 -> 206.4004 | U25: =$D25*F25 -> 206.4004 | V25: =$D25*G25 -> 206.4004 | W25: =$D25*H25 -> 206.4004 | X25: =$D25*I25 -> 206.4004 | Y25: =$D25*J25 -> 206.4004 | Z25: =$D25*K25 -> 206.4004 | AA25: =$D25*L25 -> 206.4004 | AB25: =$D25*M25 -> 206.4004 | ... AH25: =$D25*S25 -> 206.4004 | AI25: =AJ25/$AI$2 -> 0.22444585 | AJ25: =SUM(T25:AH25) -> 3096.006
A26: 10 | B26: Tempo Padrão de Mão-De-Obra [horas] | C26: MO FIAT | D26: =VLOOKUP(C26,'[1]PREÇO ATUAL'!$A$1:$D$1048576,4,0) -> 342 | E26: 1.05 | F26: 1.4 | G26: 1.1 | H26: 2.4 | I26: 1.2 | J26: 1.65 | K26: 1.05 | L26: 2.4 | M26: 1.1 | N26: 1.55 | O26: 1.05 | P26: 1.7 | Q26: 1.05 | R26: 1.4 | S26: 1.25 | T26: =$D26*E26 -> 359.1 | U26: =$D26*F26 -> 478.8 | V26: =$D26*G26 -> 376.2 | W26: =$D26*H26 -> 820.8 | X26: =$D26*I26 -> 410.4 | Y26: =$D26*J26 -> 564.3 | Z26: =$D26*K26 -> 359.1 | AA26: =$D26*L26 -> 820.8 | ... AH26: =$D26*S26 -> 427.5 | AI26: =AJ26/$AI$2 -> 0.52933884 | AJ26: =SUM(T26:AH26) -> 7301.7

Sheet CRONOS 1.3
A1: CRONOS 1.3 até MY26 | E1: PLANO DE MANUTENÇÃO | T1: CUSTOS DE MANUTENÇÃO [R$] | AI1: Total
T2: =MROUND(SUM(T4:T12),1) -> 644 | U2: =MROUND(SUM(U4:U12),1) -> 889 | V2: =MROUND(SUM(V4:V12),1) -> 661 | W2: =MROUND(SUM(W4:W12),1) -> 1918 | X2: =MROUND(SUM(X4:X12),1) -> 695 | Y2: =MROUND(SUM(Y4:Y12),1) -> 1118 | Z2: =MROUND(SUM(Z4:Z12),1) -> 644 | AA2: =MROUND(SUM(AA4:AA12),1) -> 1918 | ... AH2: =MROUND(SUM(AH4:AH12),1) -> 712 | AI2: =SUM(T2:AH2) -> 15148
A3: Nº | B3: ITENS DE SUBSTITUIÇÃO OBRIGATÓRIA | C3: PN | D3: P. PUB. | E3: 1a | F3: 2a | G3: 3a | H3: 4a | I3: 5a | J3: 6a | K3: 7a | L3: 8a | M3: 9a | N3: 10a | O3: 11 | P3: 12 | Q3: 13 | R3: 14 | S3: 15 | T3: 10000 | U3: 20000 | V3: 30000 | W3: 40000 | X3: 50000 | Y3: 60000 | Z3: 70000 | AA3: 80000 | AB3: 90000 | AC3: 100000 | AD3: =AC3+10000 -> 110000 | AE3: =AD3+10000 -> 120000 | AF3: =AE3+10000 -> 130000 | AG3: =AF3+10000 -> 140000 | AH3: =AG3+10000 -> 150000 | AI3: % 100 | AJ3: TTL 100
A4: 1 | B4: Filtro de Óleo do Motor | C4: 7094709 | D4: =VLOOKUP(C4,'[1]PREÇO ATUAL'!$A$1:$D$1048576,4,0) -> 79.9 | E4: 1 | F4: 1 | G4: 1 | H4: 1 | I4: 1 | J4: 1 | K4: 1 | L4: 1 | M4: 1 | N4: 1 | O4: 1 | P4: 1 | Q4: 1 | R4: 1 | S4: 1 | T4: =$D4*E4 -> 79.9 | U4: =$D4*F4 -> 79.9 | V4: =$D4*G4 -> 79.9 | W4: =$D4*H4 -> 79.9 | X4: =$D4*I4 -> 79.9 | Y4: =$D4*J4 -> 79.9 | Z4: =$D4*K4 -> 79.9 | AA4: =$D4*L4 -> 79.9 | ... AH4: =$D4*S4 -> 79.9 | AI4: =AJ4/$AI$2 -> 0.079119356 | AJ4: =SUM(T4:AH4) -> 1198.5
A5: 2 | B5: Filtro de Combustível | C5: 52162685 | D5: =VLOOKUP(C5,'[1]PREÇO ATUAL'!$A$1:$D$1048576,4,0) -> 35.9 | F5: 1 | H5: 1 | J5: 1 | L5: 1 | N5: 1 | P5: 1 | R5: 1 | T5: =$D5*E5 -> 0 | U5: =$D5*F5 -> 35.9 | V5: =$D5*G5 -> 0 | W5: =$D5*H5 -> 35.9 | X5: =$D5*I5 -> 0 | Y5: =$D5*J5 -> 35.9 | Z5: =$D5*K5 -> 0 | AA5: =$D5*L5 -> 35.9 | ... AH5: =$D5*S5 -> 0 | AI5: =AJ5/$AI$2 -> 0.016589649 | AJ5: =SUM(T5:AH5) -> 251.3
A6: 3 | B6: Filtro de Ar | C6: 52046268 | D6: =VLOOKUP(C6,'[1]PREÇO ATUAL'!$A$1:$D$1048576,4,0) -> 89.9 | F6: 1 | H6: 1 | J6: 1 | L6: 1 | N6: 1 | P6: 1 | R6: 1 | T6: =$D6*E6 -> 0 | U6: =$D6*F6 -> 89.9 | V6: =$D6*G6 -> 0 | W6: =$D6*H6 -> 89.9 | X6: =$D6*I6 -> 0 | Y6: =$D6*J6 -> 89.9 | Z6: =$D6*K6 -> 0 | AA6: =$D6*L6 -> 89.9 | ... AH6: =$D6*S6 -> 0 | AI6: =AJ6/$AI$2 -> 0.041543438 | AJ6: =SUM(T6:AH6) -> 629.3
A7: 4 | B7: Velas de Ignição | C7: 55267995 | D7: =VLOOKUP(C7,'[1]PREÇO ATUAL'!$A$1:$D$1048576,4,0) -> 175.9 | H7: 4 | L7: 4 | P7: 4 | T7: =$D7*E7 -> 0 | U7: =$D7*F7 -> 0 | V7: =$D7*G7 -> 0 | W7: =$D7*H7 -> 703.6 | X7: =$D7*I7 -> 0 | Y7: =$D7*J7 -> 0 | Z7: =$D7*K7 -> 0 | AA7: =$D7*L7 -> 703.6 | ... AH7: =$D7*S7 -> 0 | AI7: =AJ7/$AI$2 -> 0.13934513 | AJ7: =SUM(T7:AH7) -> 2110.8
A8: 5 | B8: Correia dos Órgãos Auxiliares | C8: 55267966 | D8: =VLOOKUP(C8,'[1]PREÇO ATUAL'!$A$1:$D$1048576,4,0) -> 143.23 | J8: 1 | P8: 1 | T8: =$D8*E8 -> 0 | U8: =$D8*F8 -> 0 | V8: =$D8*G8 -> 0 | W8: =$D8*H8 -> 0 | X8: =$D8*I8 -> 0 | Y8: =$D8*J8 -> 143.23 | Z8: =$D8*K8 -> 0 | AA8: =$D8*L8 -> 0 | ... AH8: =$D8*S8 -> 0 | AI8: =AJ8/$AI$2 -> 0.018910747 | AJ8: =SUM(T8:AH8) -> 286.46
A9: 6 | B9: Óleo da caixa de cambio mecanica - SAE 75W – API GL4 | C9: 7095576 | D9: =VLOOKUP(C9,'[1]PREÇO ATUAL'!$A$1:$D$1048576,4,0) -> 165.97812 | P9: 2 | T9: =$D9*E9 -> 0 | U9: =$D9*F9 -> 0 | V9: =$D9*G9 -> 0 | W9: =$D9*H9 -> 0 | X9: =$D9*I9 -> 0 | Y9: =$D9*J9 -> 0 | Z9: =$D9*K9 -> 0 | AA9: =$D9*L9 -> 0 | ... AH9: =$D9*S9 -> 0 | AI9: =AJ9/$AI$2 -> 0.021914196 | AJ9: =SUM(T9:AH9) -> 331.95624
A10: 7 | B10: MOPAR BRAKE FLUID DOT 4 - A cada 2 anos | C10: K04549625LA_F | D10: =VLOOKUP(C10,'[1]PREÇO ATUAL'!$A$1:$D$1048576,4,0) -> 33.622493 | T10: =$D10*E10 -> 0 | U10: =$D10*F10 -> 0 | V10: =$D10*G10 -> 0 | W10: =$D10*H10 -> 0 | X10: =$D10*I10 -> 0 | Y10: =$D10*J10 -> 0 | Z10: =$D10*K10 -> 0 | AA10: =$D10*L10 -> 0 | ... AH10: =$D10*S10 -> 0 | AI10: =AJ10/$AI$2 -> 0 | AJ10: =SUM(T10:AH10) -> 0
A11: 8 | B11: MOPAR MAXPRO SYNTHETIC 0W20 (SP/GF-6A) | C11: K68218951LA_F | D11: =VLOOKUP(C11,'[1]PREÇO ATUAL'!$A$1:$D$1048576,4,0) -> 81.26 | E11: 3.36 | F11: 3.36 | G11: 3.36 | H11: 3.36 | I11: 3.36 | J11: 3.36 | K11: 3.36 | L11: 3.36 | M11: 3.36 | N11: 3.36 | O11: 3.36 | P11: 3.36 | Q11: 3.36 | R11: 3.36 | S11: 3.36 | T11: =$D11*E11 -> 273.0336 | U11: =$D11*F11 -> 273.0336 | V11: =$D11*G11 -> 273.0336 | W11: =$D11*H11 -> 273.0336 | X11: =$D11*I11 -> 273.0336 | Y11: =$D11*J11 -> 273.0336 | Z11: =$D11*K11 -> 273.0336 | AA11: =$D11*L11 -> 273.0336 | ... AH11: =$D11*S11 -> 273.0336 | AI11: =AJ11/$AI$2 -> 0.27036599 | AJ11: =SUM(T11:AH11) -> 4095.504
A12: 9 | B12: Tempo Padrão de Mão-De-Obra [horas] | C12: MO FIAT | D12: =VLOOKUP(C12,'[1]PREÇO ATUAL'!$A$1:$D$1048576,4,0) -> 342 | E12: 0.85 | F12: 1.2 | G12: 0.9 | H12: 2.15 | I12: 1 | J12: 1.45 | K12: 0.85 | L12: 2.15 | M12: 0.9 | N12: 1.35 | O12: 0.85 | P12: 1.5 | Q12: 0.85 | R12: 1.2 | S12: 1.05 | T12: =D12*E12 -> 290.7 | U12: =$D12*F12 -> 410.4 | V12: =$D12*G12 -> 307.8 | W12: =$D12*H12 -> 735.3 | X12: =$D12*I12 -> 342 | Y12: =$D12*J12 -> 495.9 | Z12: =$D12*K12 -> 290.7 | AA12: =$D12*L12 -> 735.3 | AB12: =$D12*M12 -> 307.8 | ... AH12: =$D12*S12 -> 359.1 | AI12: =AJ12/$AI$2 -> 0.41203459 | AJ12: =SUM(T12:AH12) -> 6241.5
A14: CRONOS 1.3 MY27 MT | E14: PLANO DE MANUTENÇÃO | T14: CUSTOS DE MANUTENÇÃO [R$] | AI14: Total
T15: =MROUND(SUM(T17:T26),1) -> 914 | U15: =MROUND(SUM(U17:U26),1) -> 1160 | V15: =MROUND(SUM(V17:V26),1) -> 931 | W15: =MROUND(SUM(W17:W26),1) -> 2205 | X15: =MROUND(SUM(X17:X26),1) -> 966 | Y15: =MROUND(SUM(Y17:Y26),1) -> 1245 | Z15: =MROUND(SUM(Z17:Z26),1) -> 914 | AA15: =MROUND(SUM(AA17:AA26),1) -> 2205 | ... AH15: =MROUND(SUM(AH17:AH26),1) -> 983 | AI15: =SUM(T15:AH15) -> 18619
A16: Nº | B16: ITENS DE SUBSTITUIÇÃO OBRIGATÓRIA | C16: PN | D16: P. PUB. | E16: 1a | F16: 2a | G16: 3a | H16: 4a | I16: 5a | J16: 6a | K16: 7a | L16: 8a | M16: 9a | N16: 10a | O16: 11 | P16: 12 | Q16: 13 | R16: 14 | S16: 15 | T16: 10000 | U16: 20000 | V16: 30000 | W16: 40000 | X16: 50000 | Y16: 60000 | Z16: 70000 | AA16: 80000 | AB16: 90000 | AC16: 100000 | AD16: =AC16+10000 -> 110000 | AE16: =AD16+10000 -> 120000 | AF16: =AE16+10000 -> 130000 | AG16: =AF16+10000 -> 140000 | AH16: =AG16+10000 -> 150000 | AI16: % 100 | AJ16: TTL 100
A17: 1 | B17: Filtro de óleo do motor | C17: 7094709 | D17: =VLOOKUP(C17,'[1]PREÇO ATUAL'!$A$1:$D$1048576,4,0) -> 79.9 | E17: 1 | F17: 1 | G17: 1 | H17: 1 | I17: 1 | J17: 1 | K17: 1 | L17: 1 | M17: 1 | N17: 1 | O17: 1 | P17: 1 | Q17: 1 | R17: 1 | S17: 1 | T17: =$D17*E17 -> 79.9 | U17: =$D17*F17 -> 79.9 | V17: =$D17*G17 -> 79.9 | W17: =$D17*H17 -> 79.9 | X17: =$D17*I17 -> 79.9 | Y17: =$D17*J17 -> 79.9 | Z17: =$D17*K17 -> 79.9 | AA17: =$D17*L17 -> 79.9 | ... AH17: =$D17*S17 -> 79.9 | AI17: =AJ17/$AI$2 -> 0.079119356 | AJ17: =SUM(T17:AH17) -> 1198.5
A18: 2 | B18: Filtro de Combustível | C18: 52162685 | D18: =VLOOKUP(C18,'[1]PREÇO ATUAL'!$A$1:$D$1048576,4,0) -> 35.9 | F18: 1 | H18: 1 | J18: 1 | L18: 1 | N18: 1 | P18: 1 | R18: 1 | T18: =$D18*E18 -> 0 | U18: =$D18*F18 -> 35.9 | V18: =$D18*G18 -> 0 | W18: =$D18*H18 -> 35.9 | X18: =$D18*I18 -> 0 | Y18: =$D18*J18 -> 35.9 | Z18: =$D18*K18 -> 0 | AA18: =$D18*L18 -> 35.9 | ... AH18: =$D18*S18 -> 0 | AI18: =AJ18/$AI$2 -> 0.016589649 | AJ18: =SUM(T18:AH18) -> 251.3
A19: 3 | B19: Elemento do filtro de ar do motor | C19: 52046268 | D19: =VLOOKUP(C19,'[1]PREÇO ATUAL'!$A$1:$D$1048576,4,0) -> 89.9 | F19: 1 | H19: 1 | J19: 1 | L19: 1 | N19: 1 | P19: 1 | R19: 1 | T19: =$D19*E19 -> 0 | U19: =$D19*F19 -> 89.9 | V19: =$D19*G19 -> 0 | W19: =$D19*H19 -> 89.9 | X19: =$D19*I19 -> 0 | Y19: =$D19*J19 -> 89.9 | Z19: =$D19*K19 -> 0 | AA19: =$D19*L19 -> 89.9 | ... AH19: =$D19*S19 -> 0 | AI19: =AJ19/$AI$2 -> 0.041543438 | AJ19: =SUM(T19:AH19) -> 629.3
A20: 4 | B20: Filtro de ar limpo do canister | C20: 7096883 | D20: =VLOOKUP(C20,'[1]PREÇO ATUAL'!$A$1:$D$1048576,4,0) -> 199.05 | E20: 1 | F20: 1 | G20: 1 | H20: 1 | I20: 1 | J20: 1 | K20: 1 | L20: 1 | M20: 1 | N20: 1 | O20: 1 | P20: 1 | Q20: 1 | R20: 1 | S20: 1 | T20: =$D20*E20 -> 199.05 | U20: =$D20*F20 -> 199.05 | V20: =$D20*G20 -> 199.05 | W20: =$D20*H20 -> 199.05 | X20: =$D20*I20 -> 199.05 | Y20: =$D20*J20 -> 199.05 | Z20: =$D20*K20 -> 199.05 | AA20: =$D20*L20 -> 199.05 | ... AH20: =$D20*S20 -> 199.05 | AI20: =AJ20/$AI$2 -> 0.19710523 | AJ20: =SUM(T20:AH20) -> 2985.75
A21: 5 | B21: Velas de ignição do motor (a cada 40.000 km, independente do tempo) | C21: 55267995 | D21: =VLOOKUP(C21,'[1]PREÇO ATUAL'!$A$1:$D$1048576,4,0) -> 175.9 | H21: 4 | L21: 4 | P21: 4 | T21: =$D21*E21 -> 0 | U21: =$D21*F21 -> 0 | V21: =$D21*G21 -> 0 | W21: =$D21*H21 -> 703.6 | X21: =$D21*I21 -> 0 | Y21: =$D21*J21 -> 0 | Z21: =$D21*K21 -> 0 | AA21: =$D21*L21 -> 703.6 | ... AH21: =$D21*S21 -> 0 | AI21: =AJ21/$AI$2 -> 0.13934513 | AJ21: =SUM(T21:AH21) -> 2110.8
A22: 6 | B22: Correia dos órgão auxiliares (a cada 60.000 km ou 4 anos, o que ocorrer primeiro) | C22: 55267966 | D22: =VLOOKUP(C22,'[1]PREÇO ATUAL'!$A$1:$D$1048576,4,0) -> 143.23 | T22: =$D22*E22 -> 0 | U22: =$D22*F22 -> 0 | V22: =$D22*G22 -> 0 | W22: =$D22*H22 -> 0 | X22: =$D22*I22 -> 0 | Y22: =$D22*J22 -> 0 | Z22: =$D22*K22 -> 0 | AA22: =$D22*L22 -> 0 | ... AH22: =$D22*S22 -> 0 | AI22: =AJ22/$AI$2 -> 0 | AJ22: =SUM(T22:AH22) -> 0
A23: 7 | B23: Substituição do óleo da caixa de cambio mecanica | C23: 7095576 | D23: =VLOOKUP(C23,'[1]PREÇO ATUAL'!$A$1:$D$1048576,4,0) -> 165.97812 | T23: =$D23*E23 -> 0 | U23: =$D23*F23 -> 0 | V23: =$D23*G23 -> 0 | W23: =$D23*H23 -> 0 | X23: =$D23*I23 -> 0 | Y23: =$D23*J23 -> 0 | Z23: =$D23*K23 -> 0 | AA23: =$D23*L23 -> 0 | ... AH23: =$D23*S23 -> 0 | AI23: =AJ23/$AI$2 -> 0 | AJ23: =SUM(T23:AH23) -> 0
A24: 8 | B24: Fluído de freio (a cada 40.000 km ou 2 anos, ou que ocurrer primeiro) | C24: K04549625LA_F | D24: =VLOOKUP(C24,'[1]PREÇO ATUAL'!$A$1:$D$1048576,4,0) -> 33.622493 | T24: =$D24*E24 -> 0 | U24: =$D24*F24 -> 0 | V24: =$D24*G24 -> 0 | W24: =$D24*H24 -> 0 | X24: =$D24*I24 -> 0 | Y24: =$D24*J24 -> 0 | Z24: =$D24*K24 -> 0 | AA24: =$D24*L24 -> 0 | ... AH24: =$D24*S24 -> 0 | AI24: =AJ24/$AI$2 -> 0 | AJ24: =SUM(T24:AH24) -> 0
A25: 9 | B25: Óleo do motor - MOPAR MAXPRO SYNTHETIC 0W20 (SP/GF-6A) | C25: K68218951LA_F | D25: =VLOOKUP(C25,'[1]PREÇO ATUAL'!$A$1:$D$1048576,4,0) -> 81.26 | E25: 3.4 | F25: 3.4 | G25: 3.4 | H25: 3.4 | I25: 3.4 | J25: 3.4 | K25: 3.4 | L25: 3.4 | M25: 3.4 | N25: 3.4 | O25: 3.4 | P25: 3.4 | Q25: 3.4 | R25: 3.4 | S25: 3.4 | T25: =$D25*E25 -> 276.284 | U25: =$D25*F25 -> 276.284 | V25: =$D25*G25 -> 276.284 | W25: =$D25*H25 -> 276.284 | X25: =$D25*I25 -> 276.284 | Y25: =$D25*J25 -> 276.284 | Z25: =$D25*K25 -> 276.284 | AA25: =$D25*L25 -> 276.284 | ... AH25: =$D25*S25 -> 276.284 | AI25: =AJ25/$AI$2 -> 0.27358463 | AJ25: =SUM(T25:AH25) -> 4144.26
A26: 10 | B26: Tempo Padrão de Mão-De-Obra [horas] | C26: MO FIAT | D26: =VLOOKUP(C26,'[1]PREÇO ATUAL'!$A$1:$D$1048576,4,0) -> 342 | E26: 1.05 | F26: 1.4 | G26: 1.1 | H26: 2.4 | I26: 1.2 | J26: 1.65 | K26: 1.05 | L26: 2.4 | M26: 1.1 | N26: 1.55 | O26: 1.05 | P26: 1.7 | Q26: 1.05 | R26: 1.4 | S26: 1.25 | T26: =$D26*E26 -> 359.1 | U26: =$D26*F26 -> 478.8 | V26: =$D26*G26 -> 376.2 | W26: =$D26*H26 -> 820.8 | X26: =$D26*I26 -> 410.4 | Y26: =$D26*J26 -> 564.3 | Z26: =$D26*K26 -> 359.1 | AA26: =$D26*L26 -> 820.8 | ... AH26: =$D26*S26 -> 427.5 | AI26: =AJ26/$AI$2 -> 0.48202403 | AJ26: =SUM(T26:AH26) -> 7301.7
A28: CRONOS 1.3 MY27 AT | E28: PLANO DE MANUTENÇÃO | T28: CUSTOS DE MANUTENÇÃO [R$] | AI28: Total
T29: =MROUND(SUM(T31:T39),1) -> 914 | U29: =MROUND(SUM(U31:U39),1) -> 1160 | V29: =MROUND(SUM(V31:V39),1) -> 931 | W29: =MROUND(SUM(W31:W39),1) -> 2205 | X29: =MROUND(SUM(X31:X39),1) -> 966 | Y29: =MROUND(SUM(Y31:Y39),1) -> 1245 | Z29: =MROUND(SUM(Z31:Z39),1) -> 914 | AA29: =MROUND(SUM(AA31:AA39),1) -> 2205 | ... AH29: =MROUND(SUM(AH31:AH39),1) -> 983 | AI29: =SUM(T29:AH29) -> 18619
A30: Nº | B30: ITENS DE SUBSTITUIÇÃO OBRIGATÓRIA | C30: PN | D30: P. PUB. | E30: 1a | F30: 2a | G30: 3a | H30: 4a | I30: 5a | J30: 6a | K30: 7a | L30: 8a | M30: 9a | N30: 10a | O30: 11 | P30: 12 | Q30: 13 | R30: 14 | S30: 15 | T30: 10000 | U30: 20000 | V30: 30000 | W30: 40000 | X30: 50000 | Y30: 60000 | Z30: 70000 | AA30: 80000 | AB30: 90000 | AC30: 100000 | AD30: =AC30+10000 -> 110000 | AE30: =AD30+10000 -> 120000 | AF30: =AE30+10000 -> 130000 | AG30: =AF30+10000 -> 140000 | AH30: =AG30+10000 -> 150000 | AI30: % 100 | AJ30: TTL 100
A31: 1 | B31: Filtro de óleo do motor | C31: 7094709 | D31: =VLOOKUP(C31,'[1]PREÇO ATUAL'!$A$1:$D$1048576,4,0) -> 79.9 | E31: 1 | F31: 1 | G31: 1 | H31: 1 | I31: 1 | J31: 1 | K31: 1 | L31: 1 | M31: 1 | N31: 1 | O31: 1 | P31: 1 | Q31: 1 | R31: 1 | S31: 1 | T31: =$D31*E31 -> 79.9 | U31: =$D31*F31 -> 79.9 | V31: =$D31*G31 -> 79.9 | W31: =$D31*H31 -> 79.9 | X31: =$D31*I31 -> 79.9 | Y31: =$D31*J31 -> 79.9 | Z31: =$D31*K31 -> 79.9 | AA31: =$D31*L31 -> 79.9 | ... AH31: =$D31*S31 -> 79.9 | AI31: =AJ31/$AI$2 -> 0.079119356 | AJ31: =SUM(T31:AH31) -> 1198.5
A32: 2 | B32: Filtro de Combustível | C32: 52162685 | D32: =VLOOKUP(C32,'[1]PREÇO ATUAL'!$A$1:$D$1048576,4,0) -> 35.9 | F32: 1 | H32: 1 | J32: 1 | L32: 1 | N32: 1 | P32: 1 | R32: 1 | T32: =$D32*E32 -> 0 | U32: =$D32*F32 -> 35.9 | V32: =$D32*G32 -> 0 | W32: =$D32*H32 -> 35.9 | X32: =$D32*I32 -> 0 | Y32: =$D32*J32 -> 35.9 | Z32: =$D32*K32 -> 0 | AA32: =$D32*L32 -> 35.9 | ... AH32: =$D32*S32 -> 0 | AI32: =AJ32/$AI$2 -> 0.016589649 | AJ32: =SUM(T32:AH32) -> 251.3
A33: 3 | B33: Elemento do filtro de ar do motor | C33: 52046268 | D33: =VLOOKUP(C33,'[1]PREÇO ATUAL'!$A$1:$D$1048576,4,0) -> 89.9 | F33: 1 | H33: 1 | J33: 1 | L33: 1 | N33: 1 | P33: 1 | R33: 1 | T33: =$D33*E33 -> 0 | U33: =$D33*F33 -> 89.9 | V33: =$D33*G33 -> 0 | W33: =$D33*H33 -> 89.9 | X33: =$D33*I33 -> 0 | Y33: =$D33*J33 -> 89.9 | Z33: =$D33*K33 -> 0 | AA33: =$D33*L33 -> 89.9 | ... AH33: =$D33*S33 -> 0 | AI33: =AJ33/$AI$2 -> 0.041543438 | AJ33: =SUM(T33:AH33) -> 629.3
A34: 4 | B34: Filtro de ar limpo do canister | C34: 7096883 | D34: =VLOOKUP(C34,'[1]PREÇO ATUAL'!$A$1:$D$1048576,4,0) -> 199.05 | E34: 1 | F34: 1 | G34: 1 | H34: 1 | I34: 1 | J34: 1 | K34: 1 | L34: 1 | M34: 1 | N34: 1 | O34: 1 | P34: 1 | Q34: 1 | R34: 1 | S34: 1 | T34: =$D34*E34 -> 199.05 | U34: =$D34*F34 -> 199.05 | V34: =$D34*G34 -> 199.05 | W34: =$D34*H34 -> 199.05 | X34: =$D34*I34 -> 199.05 | Y34: =$D34*J34 -> 199.05 | Z34: =$D34*K34 -> 199.05 | AA34: =$D34*L34 -> 199.05 | ... AH34: =$D34*S34 -> 199.05 | AI34: =AJ34/$AI$2 -> 0.19710523 | AJ34: =SUM(T34:AH34) -> 2985.75
A35: 5 | B35: Velas de ignição do motor (a cada 40.000 km, independente do tempo) | C35: 55267995 | D35: =VLOOKUP(C35,'[1]PREÇO ATUAL'!$A$1:$D$1048576,4,0) -> 175.9 | H35: 4 | L35: 4 | P35: 4 | T35: =$D35*E35 -> 0 | U35: =$D35*F35 -> 0 | V35: =$D35*G35 -> 0 | W35: =$D35*H35 -> 703.6 | X35: =$D35*I35 -> 0 | Y35: =$D35*J35 -> 0 | Z35: =$D35*K35 -> 0 | AA35: =$D35*L35 -> 703.6 | ... AH35: =$D35*S35 -> 0 | AI35: =AJ35/$AI$2 -> 0.13934513 | AJ35: =SUM(T35:AH35) -> 2110.8
A36: 6 | B36: Correia dos órgão auxiliares (a cada 60.000 km ou 4 anos, o que ocorrer primeiro) | C36: 55267966 | D36: =VLOOKUP(C36,'[1]PREÇO ATUAL'!$A$1:$D$1048576,4,0) -> 143.23 | T36: =$D36*E36 -> 0 | U36: =$D36*F36 -> 0 | V36: =$D36*G36 -> 0 | W36: =$D36*H36 -> 0 | X36: =$D36*I36 -> 0 | Y36: =$D36*J36 -> 0 | Z36: =$D36*K36 -> 0 | AA36: =$D36*L36 -> 0 | ... AH36: =$D36*S36 -> 0 | AI36: =AJ36/$AI$2 -> 0 | AJ36: =SUM(T36:AH36) -> 0
A37: 7 | B37: Fluído de freio (a cada 40.000 km ou 2 anos, ou que ocurrer primeiro) | C37: K04549625LA_F | D37: =VLOOKUP(C37,'[1]PREÇO ATUAL'!$A$1:$D$1048576,4,0) -> 33.622493 | T37: =$D37*E37 -> 0 | U37: =$D37*F37 -> 0 | V37: =$D37*G37 -> 0 | W37: =$D37*H37 -> 0 | X37: =$D37*I37 -> 0 | Y37: =$D37*J37 -> 0 | Z37: =$D37*K37 -> 0 | AA37: =$D37*L37 -> 0 | ... AH37: =$D37*S37 -> 0 | AI37: =AJ37/$AI$2 -> 0 | AJ37: =SUM(T37:AH37) -> 0
A38: 8 | B38: Óleo do motor - MOPAR MAXPRO SYNTHETIC 0W20 (SP/GF-6A) | C38: K68218951LA_F | D38: =VLOOKUP(C38,'[1]PREÇO ATUAL'!$A$1:$D$1048576,4,0) -> 81.26 | E38: 3.4 | F38: 3.4 | G38: 3.4 | H38: 3.4 | I38: 3.4 | J38: 3.4 | K38: 3.4 | L38: 3.4 | M38: 3.4 | N38: 3.4 | O38: 3.4 | P38: 3.4 | Q38: 3.4 | R38: 3.4 | S38: 3.4 | T38: =$D38*E38 -> 276.284 | U38: =$D38*F38 -> 276.284 | V38: =$D38*G38 -> 276.284 | W38: =$D38*H38 -> 276.284 | X38: =$D38*I38 -> 276.284 | Y38: =$D38*J38 -> 276.284 | Z38: =$D38*K38 -> 276.284 | AA38: =$D38*L38 -> 276.284 | ... AH38: =$D38*S38 -> 276.284 | AI38: =AJ38/$AI$2 -> 0.27358463 | AJ38: =SUM(T38:AH38) -> 4144.26
A39: 9 | B39: Tempo Padrão de Mão-De-Obra [horas] | C39: MO FIAT | D39: =VLOOKUP(C39,'[1]PREÇO ATUAL'!$A$1:$D$1048576,4,0) -> 342 | E39: 1.05 | F39: 1.4 | G39: 1.1 | H39: 2.4 | I39: 1.2 | J39: 1.65 | K39: 1.05 | L39: 2.4 | M39: 1.1 | N39: 1.55 | O39: 1.05 | P39: 1.7 | Q39: 1.05 | R39: 1.4 | S39: 1.25 | T39: =$D39*E39 -> 359.1 | U39: =$D39*F39 -> 478.8 | V39: =$D39*G39 -> 376.2 | W39: =$D39*H39 -> 820.8 | X39: =$D39*I39 -> 410.4 | Y39: =$D39*J39 -> 564.3 | Z39: =$D39*K39 -> 359.1 | AA39: =$D39*L39 -> 820.8 | ... AH39: =$D39*S39 -> 427.5 | AI39: =AJ39/$AI$2 -> 0.48202403 | AJ39: =SUM(T39:AH39) -> 7301.7

Sheet CRONOS 1.8
A1: CRONOS 1.8 | E1: PLANO DE MANUTENÇÃO | T1: CUSTOS DE MANUTENÇÃO [R$] | AI1: Total
T2: =MROUND(SUM(T4:T12),1) -> 688 | U2: =MROUND(SUM(U4:U12),1) -> 928 | V2: =MROUND(SUM(V4:V12),1) -> 705 | W2: =MROUND(SUM(W4:W12),1) -> 1082 | X2: =MROUND(SUM(X4:X12),1) -> 739 | Y2: =MROUND(SUM(Y4:Y12),1) -> 2016 | Z2: =MROUND(SUM(Z4:Z12),1) -> 705 | AA2: =MROUND(SUM(AA4:AA12),1) -> 1082 | ... AH2: =MROUND(SUM(AH4:AH12),1) -> 756 | AI2: =SUM(T2:AH2) -> 15244
A3: Nº | B3: ITENS DE SUBSTITUIÇÃO OBRIGATÓRIA | C3: PN | D3: P. PUB. | E3: 1a | F3: 2a | G3: 3a | H3: 4a | I3: 5a | J3: 6a | K3: 7a | L3: 8a | M3: 9a | N3: 10a | O3: 11 | P3: 12 | Q3: 13 | R3: 14 | S3: 15 | T3: 10000 | U3: 20000 | V3: 30000 | W3: 40000 | X3: 50000 | Y3: 60000 | Z3: 70000 | AA3: 80000 | AB3: 90000 | AC3: 100000 | AD3: =AC3+10000 -> 110000 | AE3: =AD3+10000 -> 120000 | AF3: =AE3+10000 -> 130000 | AG3: =AF3+10000 -> 140000 | AH3: =AG3+10000 -> 150000 | AI3: % 100 | AJ3: TTL 100
A4: 1 | B4: Filtro de Óleo do Motor | C4: 7087808 | D4: =VLOOKUP(C4,'[1]PREÇO ATUAL'!$A$1:$D$1048576,4,0) -> 41.43 | E4: 1 | F4: 1 | G4: 1 | H4: 1 | I4: 1 | J4: 1 | K4: 1 | L4: 1 | M4: 1 | N4: 1 | O4: 1 | P4: 1 | Q4: 1 | R4: 1 | S4: 1 | T4: =$D4*E4 -> 41.43 | U4: =$D4*F4 -> 41.43 | V4: =$D4*G4 -> 41.43 | W4: =$D4*H4 -> 41.43 | X4: =$D4*I4 -> 41.43 | Y4: =$D4*J4 -> 41.43 | Z4: =$D4*K4 -> 41.43 | AA4: =$D4*L4 -> 41.43 | ... AH4: =$D4*S4 -> 41.43 | AI4: =AJ4/$AI$2 -> 0.040766859 | AJ4: =SUM(T4:AH4) -> 621.45
A5: 2 | B5: Filtro Combustível | C5: 52162685 | D5: =VLOOKUP(C5,'[1]PREÇO ATUAL'!$A$1:$D$1048576,4,0) -> 35.9 | F5: 1 | H5: 1 | J5: 1 | L5: 1 | N5: 1 | P5: 1 | R5: 1 | T5: =$D5*E5 -> 0 | U5: =$D5*F5 -> 35.9 | V5: =$D5*G5 -> 0 | W5: =$D5*H5 -> 35.9 | X5: =$D5*I5 -> 0 | Y5: =$D5*J5 -> 35.9 | Z5: =$D5*K5 -> 0 | AA5: =$D5*L5 -> 35.9 | ... AH5: =$D5*S5 -> 0 | AI5: =AJ5/$AI$2 -> 0.016485174 | AJ5: =SUM(T5:AH5) -> 251.3
A6: 3 | B6: Filtro de Ar | C6: 52062431 | D6: =VLOOKUP(C6,'[1]PREÇO ATUAL'!$A$1:$D$1048576,4,0) -> 84.9 | F6: 1 | H6: 1 | J6: 1 | L6: 1 | N6: 1 | P6: 1 | R6: 1 | T6: =$D6*E6 -> 0 | U6: =$D6*F6 -> 84.9 | V6: =$D6*G6 -> 0 | W6: =$D6*H6 -> 84.9 | X6: =$D6*I6 -> 0 | Y6: =$D6*J6 -> 84.9 | Z6: =$D6*K6 -> 0 | AA6: =$D6*L6 -> 84.9 | ... AH6: =$D6*S6 -> 0 | AI6: =AJ6/$AI$2 -> 0.03898583 | AJ6: =SUM(T6:AH6) -> 594.3
A7: 4 | B7: Vela Ignição | C7: 46348847 | D7: =VLOOKUP(C7,'[1]PREÇO ATUAL'!$A$1:$D$1048576,4,0) -> 114.24 | J7: 4 | P7: 4 | T7: =$D7*E7 -> 0 | U7: =$D7*F7 -> 0 | V7: =$D7*G7 -> 0 | W7: =$D7*H7 -> 0 | X7: =$D7*I7 -> 0 | Y7: =$D7*J7 -> 456.96 | Z7: =$D7*K7 -> 0 | AA7: =$D7*L7 -> 0 | ... AH7: =$D7*S7 -> 0 | AI7: =AJ7/$AI$2 -> 0.059952768 | AJ7: =SUM(T7:AH7) -> 913.92
A8: 5 | B8: Correia dos Orgãos Auxiliares | C8: 55258359 | D8: =VLOOKUP(C8,'[1]PREÇO ATUAL'!$A$1:$D$1048576,4,0) -> 169.01 | J8: 1 | P8: 1 | T8: =$D8*E8 -> 0 | U8: =$D8*F8 -> 0 | V8: =$D8*G8 -> 0 | W8: =$D8*H8 -> 0 | X8: =$D8*I8 -> 0 | Y8: =$D8*J8 -> 169.01 | Z8: =$D8*K8 -> 0 | AA8: =$D8*L8 -> 0 | ... AH8: =$D8*S8 -> 0 | AI8: =AJ8/$AI$2 -> 0.02217397 | AJ8: =SUM(T8:AH8) -> 338.02
A9: 6 | B9: Óleo da caixa de cambio mecanica - SAE 75W – API GL4 | C9: 7095576 | D9: =VLOOKUP(C9,'[1]PREÇO ATUAL'!$A$1:$D$1048576,4,0) -> 165.97812 | P9: 2 | T9: =$D9*E9 -> 0 | U9: =$D9*F9 -> 0 | V9: =$D9*G9 -> 0 | W9: =$D9*H9 -> 0 | X9: =$D9*I9 -> 0 | Y9: =$D9*J9 -> 0 | Z9: =$D9*K9 -> 0 | AA9: =$D9*L9 -> 0 | ... AH9: =$D9*S9 -> 0 | AI9: =AJ9/$AI$2 -> 0.02177619 | AJ9: =SUM(T9:AH9) -> 331.95624
A10: 7 | B10: MOPAR BRAKE FLUID DOT 4 - A cada 2 anos | C10: K04549625LA_F | D10: =VLOOKUP(C10,'[1]PREÇO ATUAL'!$A$1:$D$1048576,4,0) -> 33.622493 | T10: =$D10*E10 -> 0 | U10: =$D10*F10 -> 0 | V10: =$D10*G10 -> 0 | W10: =$D10*H10 -> 0 | X10: =$D10*I10 -> 0 | Y10: =$D10*J10 -> 0 | Z10: =$D10*K10 -> 0 | AA10: =$D10*L10 -> 0 | ... AH10: =$D10*S10 -> 0 | AI10: =AJ10/$AI$2 -> 0 | AJ10: =SUM(T10:AH10) -> 0
A11: 8 | B11: MOPAR MAXPRO 5W30 (SN/GF-5) | C11: K68218921LA_F | D11: =VLOOKUP(C11,'[1]PREÇO ATUAL'!$A$1:$D$1048576,4,0) -> 75.7 | E11: 4.7 | F11: 4.7 | G11: 4.7 | H11: 4.7 | I11: 4.7 | J11: 4.7 | K11: 4.7 | L11: 4.7 | M11: 4.7 | N11: 4.7 | O11: 4.7 | P11: 4.7 | Q11: 4.7 | R11: 4.7 | S11: 4.7 | T11: =$D11*E11 -> 355.79 | U11: =$D11*F11 -> 355.79 | V11: =$D11*G11 -> 355.79 | W11: =$D11*H11 -> 355.79 | X11: =$D11*I11 -> 355.79 | Y11: =$D11*J11 -> 355.79 | Z11: =$D11*K11 -> 355.79 | AA11: =$D11*L11 -> 355.79 | ... AH11: =$D11*S11 -> 355.79 | AI11: =AJ11/$AI$2 -> 0.35009512 | AJ11: =SUM(T11:AH11) -> 5336.85
A12: 9 | B12: Tempo Padrão de Mão-De-Obra [horas] | C12: MO FIAT | D12: =VLOOKUP(C12,'[1]PREÇO ATUAL'!$A$1:$D$1048576,4,0) -> 342 | E12: 0.85 | F12: 1.2 | G12: 0.9 | H12: 1.65 | I12: 1 | J12: 2.55 | K12: 0.9 | L12: 1.65 | M12: 0.9 | N12: 1.35 | O12: 0.85 | P12: 3.1 | Q12: 0.85 | R12: 1.25 | S12: 1.05 | T12: =D12*E12 -> 290.7 | U12: =$D12*F12 -> 410.4 | V12: =$D12*G12 -> 307.8 | W12: =$D12*H12 -> 564.3 | X12: =$D12*I12 -> 342 | Y12: =$D12*J12 -> 872.1 | Z12: =$D12*K12 -> 307.8 | AA12: =$D12*L12 -> 564.3 | AB12: =$D12*M12 -> 307.8 | ... AH12: =$D12*S12 -> 359.1 | AI12: =AJ12/$AI$2 -> 0.44982288 | AJ12: =SUM(T12:AH12) -> 6857.1

Sheet NOVO UNO 1.0 FIRE
A1: UNO 1.0 FIRE | E1: PLANO DE MANUTENÇÃO | O1: CUSTOS DE MANUTENÇÃO [R$] | Y1: Total
O2: =MROUND(SUM(O4:O13),1) -> 608 | P2: =MROUND(SUM(P4:P13),1) -> 813 | Q2: =MROUND(SUM(Q4:Q13),1) -> 1098 | R2: =MROUND(SUM(R4:R13),1) -> 915 | S2: =MROUND(SUM(S4:S13),1) -> 676 | T2: =MROUND(SUM(T4:T13),1) -> 2305 | U2: =MROUND(SUM(U4:U13),1) -> 608 | V2: =MROUND(SUM(V4:V13),1) -> 915 | ... X2: =MROUND(SUM(X4:X13),1) -> 847 | Y2: =SUM(O2:X2) -> 9883
A3: Nº | B3: ITENS DE SUBSTITUIÇÃO OBRIGATÓRIA | C3: PN | D3: P. PUB. | E3: 1a | F3: 2a | G3: 3a | H3: 4a | I3: 5a | J3: 6a | K3: 7a | L3: 8a | M3: 9a | N3: 10a | O3: 10000 | P3: 20000 | Q3: 30000 | R3: 40000 | S3: 50000 | T3: 60000 | U3: 70000 | V3: 80000 | W3: 90000 | X3: 100000 | Y3: % 100 | Z3: TTL 100
A4: 1 | B4: VELA IGNICAO | C4: 46480362 | D4: =VLOOKUP(C4,'[1]PREÇO ATUAL'!$A$1:$D$1048576,4,0) -> 24.15 | G4: 4 | J4: 4 | M4: 4 | O4: =$D4*E4 -> 0 | P4: =$D4*F4 -> 0 | Q4: =$D4*G4 -> 96.6 | R4: =$D4*H4 -> 0 | S4: =$D4*I4 -> 0 | T4: =$D4*J4 -> 96.6 | U4: =$D4*K4 -> 0 | V4: =$D4*L4 -> 0 | ... X4: =$D4*N4 -> 0 | Y4: =Z4/$Y$2 -> 0.02932308 | Z4: =SUM(O4:X4) -> 289.8
A5: 2 | B5: CORREIA DISTRIBUICAO | C5: 46337687 | D5: =VLOOKUP(C5,'[1]PREÇO ATUAL'!$A$1:$D$1048576,4,0) -> 136.4 | J5: 1 | O5: =$D5*E5 -> 0 | P5: =$D5*F5 -> 0 | Q5: =$D5*G5 -> 0 | R5: =$D5*H5 -> 0 | S5: =$D5*I5 -> 0 | T5: =$D5*J5 -> 136.4 | U5: =$D5*K5 -> 0 | V5: =$D5*L5 -> 0 | ... X5: =$D5*N5 -> 0 | Y5: =Z5/$Y$2 -> 0.013801477 | Z5: =SUM(O5:X5) -> 136.4
A6: 3 | B6: FILTRO OLEO | C6: 46751179 | D6: =VLOOKUP(C6,'[1]PREÇO ATUAL'!$A$1:$D$1048576,4,0) -> 71.2 | E6: 1 | F6: 1 | G6: 1 | H6: 1 | I6: 1 | J6: 1 | K6: 1 | L6: 1 | M6: 1 | N6: 1 | O6: =$D6*E6 -> 71.2 | P6: =$D6*F6 -> 71.2 | Q6: =$D6*G6 -> 71.2 | R6: =$D6*H6 -> 71.2 | S6: =$D6*I6 -> 71.2 | T6: =$D6*J6 -> 71.2 | U6: =$D6*K6 -> 71.2 | V6: =$D6*L6 -> 71.2 | ... X6: =$D6*N6 -> 71.2 | Y6: =Z6/$Y$2 -> 0.072042902 | Z6: =SUM(O6:X6) -> 712
A7: 4 | B7: FILTRO COMBUSTIVEL | C7: 52162685 | D7: =VLOOKUP(C7,'[1]PREÇO ATUAL'!$A$1:$D$1048576,4,0) -> 35.9 | F7: 1 | H7: 1 | J7: 1 | L7: 1 | N7: 1 | O7: =$D7*E7 -> 0 | P7: =$D7*F7 -> 35.9 | Q7: =$D7*G7 -> 0 | R7: =$D7*H7 -> 35.9 | S7: =$D7*I7 -> 0 | T7: =$D7*J7 -> 35.9 | U7: =$D7*K7 -> 0 | V7: =$D7*L7 -> 35.9 | ... X7: =$D7*N7 -> 35.9 | Y7: =Z7/$Y$2 -> 0.018162501 | Z7: =SUM(O7:X7) -> 179.5
A8: 5 | B8: ELEMENTO FILTRANTE | C8: 51854598 | D8: =VLOOKUP(C8,'[1]PREÇO ATUAL'!$A$1:$D$1048576,4,0) -> 83.06 | F8: 1 | H8: 1 | J8: 1 | L8: 1 | N8: 1 | O8: =$D8*E8 -> 0 | P8: =$D8*F8 -> 83.06 | Q8: =$D8*G8 -> 0 | R8: =$D8*H8 -> 83.06 | S8: =$D8*I8 -> 0 | T8: =$D8*J8 -> 83.06 | U8: =$D8*K8 -> 0 | V8: =$D8*L8 -> 83.06 | ... X8: =$D8*N8 -> 83.06 | Y8: =Z8/$Y$2 -> 0.042021653 | Z8: =SUM(O8:X8) -> 415.3
A9: 6 | B9: CORREIA TRANSMISSAO C/ AC | C9: 55236185 | D9: =VLOOKUP(C9,'[1]PREÇO ATUAL'!$A$1:$D$1048576,4,0) -> 139.9 | J9: 1 | O9: =$D9*E9 -> 0 | P9: =$D9*F9 -> 0 | Q9: =$D9*G9 -> 0 | R9: =$D9*H9 -> 0 | S9: =$D9*I9 -> 0 | T9: =$D9*J9 -> 139.9 | U9: =$D9*K9 -> 0 | V9: =$D9*L9 -> 0 | ... X9: =$D9*N9 -> 0 | Y9: =Z9/$Y$2 -> 0.014155621 | Z9: =SUM(O9:X9) -> 139.9
A10: 7 | B10: CORREIA TRANSMISSAO DH | C10: 46744566 | D10: =VLOOKUP(C10,'[1]PREÇO ATUAL'!$A$1:$D$1048576,4,0) -> 25.55 | J10: 1 | O10: =$D10*E10 -> 0 | P10: =$D10*F10 -> 0 | Q10: =$D10*G10 -> 0 | R10: =$D10*H10 -> 0 | S10: =$D10*I10 -> 0 | T10: =$D10*J10 -> 25.55 | U10: =$D10*K10 -> 0 | V10: =$D10*L10 -> 0 | ... X10: =$D10*N10 -> 0 | Y10: =Z10/$Y$2 -> 0.0025852474 | Z10: =SUM(O10:X10) -> 25.55
A11: 8 | B11: MOPAR MAXPRO 5W30 (SN/GF-5) | C11: K68218921LA_F | D11: =VLOOKUP(C11,'[1]PREÇO ATUAL'!$A$1:$D$1048576,4,0) -> 75.7 | E11: 2.8 | F11: 2.8 | G11: 2.8 | H11: 2.8 | I11: 2.8 | J11: 2.8 | K11: 2.8 | L11: 2.8 | M11: 2.8 | N11: 2.8 | O11: =$D11*E11 -> 211.96 | P11: =$D11*F11 -> 211.96 | Q11: =$D11*G11 -> 211.96 | R11: =$D11*H11 -> 211.96 | S11: =$D11*I11 -> 211.96 | T11: =$D11*J11 -> 211.96 | U11: =$D11*K11 -> 211.96 | V11: =$D11*L11 -> 211.96 | ... X11: =$D11*N11 -> 211.96 | Y11: =Z11/$Y$2 -> 0.21446929 | Z11: =SUM(O11:X11) -> 2119.6
A12: 9 | B12: MOPAR BRAKE FLUID DOT 4 - A cada 2 anos | C12: K04549625LA_F | D12: =VLOOKUP(C12,'[1]PREÇO ATUAL'!$A$1:$D$1048576,4,0) -> 33.622493 | O12: =$D12*E12 -> 0 | P12: =$D12*F12 -> 0 | Q12: =$D12*G12 -> 0 | R12: =$D12*H12 -> 0 | S12: =$D12*I12 -> 0 | T12: =$D12*J12 -> 0 | U12: =$D12*K12 -> 0 | V12: =$D12*L12 -> 0 | ... X12: =$D12*N12 -> 0 | Y12: =Z12/$Y$2 -> 0 | Z12: =SUM(O12:X12) -> 0
A13: 10 | B13: Tempo Padrão de Mão-De-Obra [horas] | C13: MO FIAT | D13: =VLOOKUP(C13,'[1]PREÇO ATUAL'!$A$1:$D$1048576,4,0) -> 342 | E13: 0.95 | F13: 1.2 | G13: 2.1 | H13: 1.5 | I13: 1.15 | J13: 4.4 | K13: 0.95 | L13: 1.5 | M13: 2.1 | N13: 1.3 | O13: =D13*E13 -> 324.9 | P13: =$D13*F13 -> 410.4 | Q13: =$D13*G13 -> 718.2 | R13: =$D13*H13 -> 513 | S13: =$D13*I13 -> 393.3 | T13: =$D13*J13 -> 1504.8 | U13: =$D13*K13 -> 324.9 | V13: =$D13*L13 -> 513 | W13: =$D13*M13 -> 718.2 | X13: =$D13*N13 -> 444.6 | Y13: =Z13/$Y$2 -> 0.59347364 | Z13: =SUM(O13:X13) -> 5865.3

Sheet NOVO UNO 1.0 FIREFLY
A1: UNO 1.0 FIREFLY | E1: PLANO DE MANUTENÇÃO | O1: CUSTOS DE MANUTENÇÃO [R$] | Y1: Total
O2: =MROUND(SUM(O4:O11),1) -> 577 | P2: =MROUND(SUM(P4:P11),1) -> 788 | Q2: =MROUND(SUM(Q4:Q11),1) -> 611 | R2: =MROUND(SUM(R4:R11),1) -> 1419 | S2: =MROUND(SUM(S4:S11),1) -> 628 | T2: =MROUND(SUM(T4:T11),1) -> 1171 | U2: =MROUND(SUM(U4:U11),1) -> 577 | V2: =MROUND(SUM(V4:V11),1) -> 1419 | ... X2: =MROUND(SUM(X4:X11),1) -> 840 | Y2: =SUM(O2:X2) -> 8641
A3: Nº | B3: ITENS DE SUBSTITUIÇÃO OBRIGATÓRIA | C3: PN | D3: P. PUB. | E3: 1a | F3: 2a | G3: 3a | H3: 4a | I3: 5a | J3: 6a | K3: 7a | L3: 8a | M3: 9a | N3: 10a | O3: 10000 | P3: 20000 | Q3: 30000 | R3: 40000 | S3: 50000 | T3: 60000 | U3: 70000 | V3: 80000 | W3: 90000 | X3: 100000 | Y3: % 100 | Z3: TTL 100
A4: 1 | B4: Filtro de Óleo do Motor | C4: 7094709 | D4: =VLOOKUP(C4,'[1]PREÇO ATUAL'!$A$1:$D$1048576,4,0) -> 79.9 | E4: 1 | F4: 1 | G4: 1 | H4: 1 | I4: 1 | J4: 1 | K4: 1 | L4: 1 | M4: 1 | N4: 1 | O4: =$D4*E4 -> 79.9 | P4: =$D4*F4 -> 79.9 | Q4: =$D4*G4 -> 79.9 | R4: =$D4*H4 -> 79.9 | S4: =$D4*I4 -> 79.9 | T4: =$D4*J4 -> 79.9 | U4: =$D4*K4 -> 79.9 | V4: =$D4*L4 -> 79.9 | ... X4: =$D4*N4 -> 79.9 | Y4: =Z4/$Y$2 -> 0.09246615 | Z4: =SUM(O4:X4) -> 799
A5: 2 | B5: Filtro de Combustível | C5: 52162685 | D5: =VLOOKUP(C5,'[1]PREÇO ATUAL'!$A$1:$D$1048576,4,0) -> 35.9 | F5: 1 | H5: 1 | J5: 1 | L5: 1 | N5: 1 | O5: =$D5*E5 -> 0 | P5: =$D5*F5 -> 35.9 | Q5: =$D5*G5 -> 0 | R5: =$D5*H5 -> 35.9 | S5: =$D5*I5 -> 0 | T5: =$D5*J5 -> 35.9 | U5: =$D5*K5 -> 0 | V5: =$D5*L5 -> 35.9 | ... X5: =$D5*N5 -> 35.9 | Y5: =Z5/$Y$2 -> 0.020773059 | Z5: =SUM(O5:X5) -> 179.5
A6: 3 | B6: Filtro de Ar | C6: 52046268 | D6: =VLOOKUP(C6,'[1]PREÇO ATUAL'!$A$1:$D$1048576,4,0) -> 89.9 | F6: 1 | H6: 1 | J6: 1 | L6: 1 | N6: 1 | O6: =$D6*E6 -> 0 | P6: =$D6*F6 -> 89.9 | Q6: =$D6*G6 -> 0 | R6: =$D6*H6 -> 89.9 | S6: =$D6*I6 -> 0 | T6: =$D6*J6 -> 89.9 | U6: =$D6*K6 -> 0 | V6: =$D6*L6 -> 89.9 | ... X6: =$D6*N6 -> 89.9 | Y6: =Z6/$Y$2 -> 0.052019442 | Z6: =SUM(O6:X6) -> 449.5
A7: 4 | B7: Vela de Ignição | C7: 55267995 | D7: =VLOOKUP(C7,'[1]PREÇO ATUAL'!$A$1:$D$1048576,4,0) -> 175.9 | H7: 3 | L7: 3 | O7: =$D7*E7 -> 0 | P7: =$D7*F7 -> 0 | Q7: =$D7*G7 -> 0 | R7: =$D7*H7 -> 527.7 | S7: =$D7*I7 -> 0 | T7: =$D7*J7 -> 0 | U7: =$D7*K7 -> 0 | V7: =$D7*L7 -> 527.7 | ... X7: =$D7*N7 -> 0 | Y7: =Z7/$Y$2 -> 0.12213864 | Z7: =SUM(O7:X7) -> 1055.4
A8: 5 | B8: Correia dos Órgãos Auxiliares | C8: 55267966 | D8: =VLOOKUP(C8,'[1]PREÇO ATUAL'!$A$1:$D$1048576,4,0) -> 143.23 | J8: 1 | O8: =$D8*E8 -> 0 | P8: =$D8*F8 -> 0 | Q8: =$D8*G8 -> 0 | R8: =$D8*H8 -> 0 | S8: =$D8*I8 -> 0 | T8: =$D8*J8 -> 143.23 | U8: =$D8*K8 -> 0 | V8: =$D8*L8 -> 0 | ... X8: =$D8*N8 -> 0 | Y8: =Z8/$Y$2 -> 0.016575628 | Z8: =SUM(O8:X8) -> 143.23
A9: 6 | B9: MOPAR BRAKE FLUID DOT 4 - A cada 2 anos | C9: K04549625LA_F | D9: =VLOOKUP(C9,'[1]PREÇO ATUAL'!$A$1:$D$1048576,4,0) -> 33.622493 | O9: =$D9*E9 -> 0 | P9: =$D9*F9 -> 0 | Q9: =$D9*G9 -> 0 | R9: =$D9*H9 -> 0 | S9: =$D9*I9 -> 0 | T9: =$D9*J9 -> 0 | U9: =$D9*K9 -> 0 | V9: =$D9*L9 -> 0 | ... X9: =$D9*N9 -> 0 | Y9: =Z9/$Y$2 -> 0 | Z9: =SUM(O9:X9) -> 0
A10: 7 | B10: MOPAR MAXPRO SYNTHETIC 0W20 (SP/GF-6A) | C10: K68218951LA_F | D10: =VLOOKUP(C10,'[1]PREÇO ATUAL'!$A$1:$D$1048576,4,0) -> 81.26 | E10: 2.54 | F10: 2.54 | G10: 2.54 | H10: 2.54 | I10: 2.54 | J10: 2.54 | K10: 2.54 | L10: 2.54 | M10: 2.54 | N10: 2.54 | O10: =$D10*E10 -> 206.4004 | P10: =$D10*F10 -> 206.4004 | Q10: =$D10*G10 -> 206.4004 | R10: =$D10*H10 -> 206.4004 | S10: =$D10*I10 -> 206.4004 | T10: =$D10*J10 -> 206.4004 | U10: =$D10*K10 -> 206.4004 | V10: =$D10*L10 -> 206.4004 | ... X10: =$D10*N10 -> 206.4004 | Y10: =Z10/$Y$2 -> 0.23886171 | Z10: =SUM(O10:X10) -> 2064.004
A11: 8 | B11: Tempo Padrão de Mão-De-Obra [horas] | C11: MO FIAT | D11: =VLOOKUP(C11,'[1]PREÇO ATUAL'!$A$1:$D$1048576,4,0) -> 342 | E11: 0.85 | F11: 1.1 | G11: 0.95 | H11: 1.4 | I11: 1 | J11: 1.8 | K11: 0.85 | L11: 1.4 | M11: 0.95 | N11: 1.25 | O11: =D11*E11 -> 290.7 | P11: =$D11*F11 -> 376.2 | Q11: =$D11*G11 -> 324.9 | R11: =$D11*H11 -> 478.8 | S11: =$D11*I11 -> 342 | T11: =$D11*J11 -> 615.6 | U11: =$D11*K11 -> 290.7 | V11: =$D11*L11 -> 478.8 | W11: =$D11*M11 -> 324.9 | X11: =$D11*N11 -> 427.5 | Y11: =Z11/$Y$2 -> 0.45713459 | Z11: =SUM(O11:X11) -> 3950.1

Sheet NOVO UNO 1.3 FIREFLY
A1: UNO 1.3 FIREFLY | E1: PLANO DE MANUTENÇÃO | O1: CUSTOS DE MANUTENÇÃO [R$] | Y1: Total
O2: =MROUND(SUM(O4:O11),1) -> 644 | P2: =MROUND(SUM(P4:P11),1) -> 855 | Q2: =MROUND(SUM(Q4:Q11),1) -> 678 | R2: =MROUND(SUM(R4:R11),1) -> 1661 | S2: =MROUND(SUM(S4:S11),1) -> 695 | T2: =MROUND(SUM(T4:T11),1) -> 1238 | U2: =MROUND(SUM(U4:U11),1) -> 644 | V2: =MROUND(SUM(V4:V11),1) -> 1661 | ... X2: =MROUND(SUM(X4:X11),1) -> 906 | Y2: =SUM(O2:X2) -> 9660
A3: Nº | B3: ITENS DE SUBSTITUIÇÃO OBRIGATÓRIA | C3: PN | D3: P. PUB. | E3: 1a | F3: 2a | G3: 3a | H3: 4a | I3: 5a | J3: 6a | K3: 7a | L3: 8a | M3: 9a | N3: 10a | O3: 10000 | P3: 20000 | Q3: 30000 | R3: 40000 | S3: 50000 | T3: 60000 | U3: 70000 | V3: 80000 | W3: 90000 | X3: 100000 | Y3: % 100 | Z3: TTL 100
A4: 1 | B4: Filtro de Óleo do Motor | C4: 7094709 | D4: =VLOOKUP(C4,'[1]PREÇO ATUAL'!$A$1:$D$1048576,4,0) -> 79.9 | E4: 1 | F4: 1 | G4: 1 | H4: 1 | I4: 1 | J4: 1 | K4: 1 | L4: 1 | M4: 1 | N4: 1 | O4: =$D4*E4 -> 79.9 | P4: =$D4*F4 -> 79.9 | Q4: =$D4*G4 -> 79.9 | R4: =$D4*H4 -> 79.9 | S4: =$D4*I4 -> 79.9 | T4: =$D4*J4 -> 79.9 | U4: =$D4*K4 -> 79.9 | V4: =$D4*L4 -> 79.9 | ... X4: =$D4*N4 -> 79.9 | Y4: =Z4/$Y$2 -> 0.082712215 | Z4: =SUM(O4:X4) -> 799
A5: 2 | B5: Filtro de Combustível | C5: 52162685 | D5: =VLOOKUP(C5,'[1]PREÇO ATUAL'!$A$1:$D$1048576,4,0) -> 35.9 | F5: 1 | H5: 1 | J5: 1 | L5: 1 | N5: 1 | O5: =$D5*E5 -> 0 | P5: =$D5*F5 -> 35.9 | Q5: =$D5*G5 -> 0 | R5: =$D5*H5 -> 35.9 | S5: =$D5*I5 -> 0 | T5: =$D5*J5 -> 35.9 | U5: =$D5*K5 -> 0 | V5: =$D5*L5 -> 35.9 | ... X5: =$D5*N5 -> 35.9 | Y5: =Z5/$Y$2 -> 0.018581781 | Z5: =SUM(O5:X5) -> 179.5
A6: 3 | B6: Filtro de Ar | C6: 52046268 | D6: =VLOOKUP(C6,'[1]PREÇO ATUAL'!$A$1:$D$1048576,4,0) -> 89.9 | F6: 1 | H6: 1 | J6: 1 | L6: 1 | N6: 1 | O6: =$D6*E6 -> 0 | P6: =$D6*F6 -> 89.9 | Q6: =$D6*G6 -> 0 | R6: =$D6*H6 -> 89.9 | S6: =$D6*I6 -> 0 | T6: =$D6*J6 -> 89.9 | U6: =$D6*K6 -> 0 | V6: =$D6*L6 -> 89.9 | ... X6: =$D6*N6 -> 89.9 | Y6: =Z6/$Y$2 -> 0.046532091 | Z6: =SUM(O6:X6) -> 449.5
A7: 4 | B7: Vela de Ignição | C7: 55267995 | D7: =VLOOKUP(C7,'[1]PREÇO ATUAL'!$A$1:$D$1048576,4,0) -> 175.9 | H7: 4 | L7: 4 | O7: =$D7*E7 -> 0 | P7: =$D7*F7 -> 0 | Q7: =$D7*G7 -> 0 | R7: =$D7*H7 -> 703.6 | S7: =$D7*I7 -> 0 | T7: =$D7*J7 -> 0 | U7: =$D7*K7 -> 0 | V7: =$D7*L7 -> 703.6 | ... X7: =$D7*N7 -> 0 | Y7: =Z7/$Y$2 -> 0.14567288 | Z7: =SUM(O7:X7) -> 1407.2
A8: 5 | B8: Correia dos Órgãos Auxiliares | C8: 55267966 | D8: =VLOOKUP(C8,'[1]PREÇO ATUAL'!$A$1:$D$1048576,4,0) -> 143.23 | J8: 1 | O8: =$D8*E8 -> 0 | P8: =$D8*F8 -> 0 | Q8: =$D8*G8 -> 0 | R8: =$D8*H8 -> 0 | S8: =$D8*I8 -> 0 | T8: =$D8*J8 -> 143.23 | U8: =$D8*K8 -> 0 | V8: =$D8*L8 -> 0 | ... X8: =$D8*N8 -> 0 | Y8: =Z8/$Y$2 -> 0.014827122 | Z8: =SUM(O8:X8) -> 143.23
A9: 6 | B9: MOPAR BRAKE FLUID DOT 4 - A cada 2 anos | C9: K04549625LA_F | D9: =VLOOKUP(C9,'[1]PREÇO ATUAL'!$A$1:$D$1048576,4,0) -> 33.622493 | O9: =$D9*E9 -> 0 | P9: =$D9*F9 -> 0 | Q9: =$D9*G9 -> 0 | R9: =$D9*H9 -> 0 | S9: =$D9*I9 -> 0 | T9: =$D9*J9 -> 0 | U9: =$D9*K9 -> 0 | V9: =$D9*L9 -> 0 | ... X9: =$D9*N9 -> 0 | Y9: =Z9/$Y$2 -> 0 | Z9: =SUM(O9:X9) -> 0
